Workbook

Sheet Curvas Futuros
C1: LATEST PRICE | T1: AVG. PRICE | W1: $ | Y1: OPEN INTEREST | AP1: Open $ | AQ1: Prev Close $
C2: LC2401 | D2: LC2402 | E2: LC2403 | F2: LC2404 | G2: LC2405 | H2: LC2406 | I2: LC2407 | J2: LC2408 | K2: LC2409 | L2: LC2410 | M2: LC2411 | N2: LC2412 | O2: LC2501 | P2: LC2502 | Q2: LC2503 | R2: LC2504 | S2: AVRG | T2: Battery | U2: Industrial | W2: #VALUE! | X2: {=_FV(W2,"Previous close",TRUE)} -> #VALUE! | Y2: LC2401 | Z2: LC2402 | AA2: LC2403 | AB2: LC2404 | AC2: LC2405 | AD2: LC2406 | AE2: LC2407 | AF2: LC2408 | AG2: LC2409 | AH2: LC2410 | AI2: LC2411 | AJ2: LC2412 | AK2: LC2501 | AL2: LC2502 | AM2: LC2503 | AN2: LC2504 | AO2: TOTAL | AP2: {=_FV(W2,"Open")} -> #VALUE! | AQ2: {=_FV(W2,"Previous close",TRUE)} -> #VALUE!
A3: DATE | B3: 45238 | C3: =+'lc2401'!B2*W3/1000 -> 23.256 | D3: =+'lc2402'!B2*W3/1000 -> 21.76 | E3: =+'lc2403'!B2*W3/1000 -> 21.072 | F3: =+'lc2404'!B2*W3/1000 -> 20.832 | G3: =+'lc2405'!B2*W3/1000 -> 20.536 | H3: =+'lc2406'!B2*W3/1000 -> 20.176 | I3: =+'lc2407'!B2*W3/1000 -> 19.944 | J3: =+'lc2408'!B2*W3/1000 -> 19.68 | K3: =+'lc2409'!B2*W3/1000 -> 19.352 | L3: =+'lc2410'!B2*W3/1000 -> 0 | M3: =+'lc2411'!B2*W3/1000 -> 0 | N3: =+'lc2412'!B2*W3/1000 -> 0 | O3: =+'lc2501'!B2*W3/1000 -> 0 | P3: 0 | Q3: 0 | S3: =+AVERAGE(C3:O3) -> 14.354462 | T3: 0 | U3: 0 | W3: 0.16 | Y3: =+'lc2401'!G2 -> 105467 | Z3: =+'lc2402'!G2 -> 5489 | AA3: =+'lc2403'!G2 -> 3464 | AB3: =+'lc2404'!G2 -> 3424 | AC3: =+'lc2405'!G2 -> 5244 | AD3: =+'lc2406'!G2 -> 3897 | AE3: =+'lc2407'!G2 -> 53080 | AF3: =+'lc2408'!G2 -> 5687 | AG3: =+'lc2409'!G2 -> 10288 | AH3: =+'lc2410'!G2 -> 0 | AI3: =+'lc2411'!G2 -> 0 | AK3: =+'lc2501'!G2 -> 0 | AO3: =+SUM(Y3:AL3) -> 196040 | AP3: 0
B4: 45239 | C4: =+'lc2401'!B3*W4/1000 -> 23.064 | D4: =+'lc2402'!B3*W4/1000 -> 21.712 | E4: =+'lc2403'!B3*W4/1000 -> 21.096 | F4: =+'lc2404'!B3*W4/1000 -> 20.864 | G4: =+'lc2405'!B3*W4/1000 -> 20.576 | H4: =+'lc2406'!B3*W4/1000 -> 20.176 | I4: =+'lc2407'!B3*W4/1000 -> 19.952 | J4: =+'lc2408'!B3*W4/1000 -> 19.656 | K4: =+'lc2409'!B3*W4/1000 -> 19.344 | L4: =+'lc2410'!B3*W4/1000 -> 0 | M4: =+'lc2411'!B3*W4/1000 -> 0 | N4: =+'lc2412'!B3*W4/1000 -> 0 | O4: =+'lc2501'!B3*W4/1000 -> 0 | P4: 0 | Q4: 0 | S4: =+AVERAGE(C4:O4) -> 14.341538 | T4: 0 | U4: 0 | W4: 0.16 | Y4: =+'lc2401'!G3 -> 106948 | Z4: =+'lc2402'!G3 -> 5501 | AA4: =+'lc2403'!G3 -> 3495 | AB4: =+'lc2404'!G3 -> 3565 | AC4: =+'lc2405'!G3 -> 5277 | AD4: =+'lc2406'!G3 -> 3880 | AE4: =+'lc2407'!G3 -> 52858 | AF4: =+'lc2408'!G3 -> 5768 | AG4: =+'lc2409'!G3 -> 10234 | AH4: =+'lc2410'!G3 -> 0 | AI4: =+'lc2411'!G3 -> 0 | AK4: =+'lc2501'!G3 -> 0 | AO4: =+SUM(Y4:AL4) -> 197526 | AP4: =+AO4/AO3-1 -> 0.0075800857
B5: 45240 | C5: =+'lc2401'!B4*W5/1000 -> 23.824 | D5: =+'lc2402'!B4*W5/1000 -> 22.368 | E5: =+'lc2403'!B4*W5/1000 -> 21.68 | F5: =+'lc2404'!B4*W5/1000 -> 21.544 | G5: =+'lc2405'!B4*W5/1000 -> 21.224 | H5: =+'lc2406'!B4*W5/1000 -> 20.888 | I5: =+'lc2407'!B4*W5/1000 -> 20.68 | J5: =+'lc2408'!B4*W5/1000 -> 20.328 | K5: =+'lc2409'!B4*W5/1000 -> 19.968 | L5: =+'lc2410'!B4*W5/1000 -> 0 | M5: =+'lc2411'!B4*W5/1000 -> 0 | N5: =+'lc2412'!B4*W5/1000 -> 0 | O5: =+'lc2501'!B4*W5/1000 -> 0 | P5: 0 | Q5: 0 | S5: =+AVERAGE(C5:O5) -> 14.808 | T5: 0 | U5: 0 | W5: 0.16 | Y5: =+'lc2401'!G4 -> 98275 | Z5: =+'lc2402'!G4 -> 5262 | AA5: =+'lc2403'!G4 -> 3412 | AB5: =+'lc2404'!G4 -> 3891 | AC5: =+'lc2405'!G4 -> 5316 | AD5: =+'lc2406'!G4 -> 3855 | AE5: =+'lc2407'!G4 -> 53766 | AF5: =+'lc2408'!G4 -> 5677 | AG5: =+'lc2409'!G4 -> 9884 | AH5: =+'lc2410'!G4 -> 0 | AI5: =+'lc2411'!G4 -> 0 | AK5: =+'lc2501'!G4 -> 0 | AO5: =+SUM(Y5:AL5) -> 189338 | AP5: =+AO5/AO4-1 -> -0.041452771
B6: 45243 | C6: =+'lc2401'!B5*W6/1000 -> 22.664 | D6: =+'lc2402'!B5*W6/1000 -> 21.528 | E6: =+'lc2403'!B5*W6/1000 -> 21.04 | F6: =+'lc2404'!B5*W6/1000 -> 20.904 | G6: =+'lc2405'!B5*W6/1000 -> 20.672 | H6: =+'lc2406'!B5*W6/1000 -> 20.36 | I6: =+'lc2407'!B5*W6/1000 -> 20.096 | J6: =+'lc2408'!B5*W6/1000 -> 19.832 | K6: =+'lc2409'!B5*W6/1000 -> 19.544 | L6: =+'lc2410'!B5*W6/1000 -> 0 | M6: =+'lc2411'!B5*W6/1000 -> 0 | N6: =+'lc2412'!B5*W6/1000 -> 0 | O6: =+'lc2501'!B5*W6/1000 -> 0 | P6: 0 | Q6: 0 | S6: =+AVERAGE(C6:O6) -> 14.356923 | T6: 0 | U6: 0 | W6: 0.16 | Y6: =+'lc2401'!G5 -> 96195 | Z6: =+'lc2402'!G5 -> 5545 | AA6: =+'lc2403'!G5 -> 3497 | AB6: =+'lc2404'!G5 -> 4076 | AC6: =+'lc2405'!G5 -> 5537 | AD6: =+'lc2406'!G5 -> 3868 | AE6: =+'lc2407'!G5 -> 55395 | AF6: =+'lc2408'!G5 -> 5673 | AG6: =+'lc2409'!G5 -> 9663 | AH6: =+'lc2410'!G5 -> 0 | AI6: =+'lc2411'!G5 -> 0 | AJ6: =+'lc2412'!G5 -> 0 | AK6: =+'lc2501'!G5 -> 0 | AO6: =+SUM(Y6:AL6) -> 189449 | AP6: =+AO6/AO5-1 -> 0.00058625316
B7: 45244 | C7: =+'lc2401'!B6*W7/1000 -> 22.808 | D7: =+'lc2402'!B6*W7/1000 -> 21.8 | E7: =+'lc2403'!B6*W7/1000 -> 21.272 | F7: =+'lc2404'!B6*W7/1000 -> 20.976 | G7: =+'lc2405'!B6*W7/1000 -> 20.664 | H7: =+'lc2406'!B6*W7/1000 -> 20.336 | I7: =+'lc2407'!B6*W7/1000 -> 20.096 | J7: =+'lc2408'!B6*W7/1000 -> 19.872 | K7: =+'lc2409'!B6*W7/1000 -> 19.6 | L7: =+'lc2410'!B6*W7/1000 -> 0 | M7: =+'lc2411'!B6*W7/1000 -> 0 | N7: =+'lc2412'!B6*W7/1000 -> 0 | O7: =+'lc2501'!B6*W7/1000 -> 0 | P7: 0 | Q7: 0 | S7: =+AVERAGE(C7:O7) -> 14.417231 | T7: 0 | U7: 0 | W7: 0.16 | Y7: =+'lc2401'!G6 -> 99509 | Z7: =+'lc2402'!G6 -> 5802 | AA7: =+'lc2403'!G6 -> 3233 | AB7: =+'lc2404'!G6 -> 3965 | AC7: =+'lc2405'!G6 -> 5714 | AD7: =+'lc2406'!G6 -> 3850 | AE7: =+'lc2407'!G6 -> 55084 | AF7: =+'lc2408'!G6 -> 5653 | AG7: =+'lc2409'!G6 -> 9738 | AH7: =+'lc2410'!G6 -> 0 | AI7: =+'lc2411'!G6 -> 0 | AJ7: =+'lc2412'!G6 -> 0 | AK7: =+'lc2501'!G6 -> 0 | AO7: =+SUM(Y7:AL7) -> 192548 | AP7: =+AO7/AO6-1 -> 0.016357964
B8: 45245 | C8: =+'lc2401'!B7*W8/1000 -> 22.816 | D8: =+'lc2402'!B7*W8/1000 -> 21.872 | E8: =+'lc2403'!B7*W8/1000 -> 21.312 | F8: =+'lc2404'!B7*W8/1000 -> 21.072 | G8: =+'lc2405'!B7*W8/1000 -> 20.832 | H8: =+'lc2406'!B7*W8/1000 -> 20.504 | I8: =+'lc2407'!B7*W8/1000 -> 20.32 | J8: =+'lc2408'!B7*W8/1000 -> 20.088 | K8: =+'lc2409'!B7*W8/1000 -> 19.832 | L8: =+'lc2410'!B7*W8/1000 -> 0 | M8: =+'lc2411'!B7*W8/1000 -> 0 | N8: =+'lc2412'!B7*W8/1000 -> 0 | O8: =+'lc2501'!B7*W8/1000 -> 0 | P8: 0 | Q8: 0 | S8: =+AVERAGE(C8:O8) -> 14.511385 | T8: 0 | U8: 0 | W8: 0.16 | Y8: =+'lc2401'!G7 -> 107801 | Z8: =+'lc2402'!G7 -> 6023 | AA8: =+'lc2403'!G7 -> 3227 | AB8: =+'lc2404'!G7 -> 4059 | AC8: =+'lc2405'!G7 -> 5750 | AD8: =+'lc2406'!G7 -> 3864 | AE8: =+'lc2407'!G7 -> 57820 | AF8: =+'lc2408'!G7 -> 5651 | AG8: =+'lc2409'!G7 -> 9647 | AH8: =+'lc2410'!G7 -> 0 | AI8: =+'lc2411'!G7 -> 0 | AJ8: =+'lc2412'!G7 -> 0 | AK8: =+'lc2501'!G7 -> 0 | AO8: =+SUM(Y8:AL8) -> 203842 | AP8: =+AO8/AO7-1 -> 0.058655504
B9: 45246 | C9: =+'lc2401'!B8*W9/1000 -> 22.544 | D9: =+'lc2402'!B8*W9/1000 -> 21.744 | E9: =+'lc2403'!B8*W9/1000 -> 21.216 | F9: =+'lc2404'!B8*W9/1000 -> 21.016 | G9: =+'lc2405'!B8*W9/1000 -> 20.816 | H9: =+'lc2406'!B8*W9/1000 -> 20.504 | I9: =+'lc2407'!B8*W9/1000 -> 20.344 | J9: =+'lc2408'!B8*W9/1000 -> 20.144 | K9: =+'lc2409'!B8*W9/1000 -> 19.944 | L9: =+'lc2410'!B8*W9/1000 -> 0 | M9: =+'lc2411'!B8*W9/1000 -> 0 | N9: =+'lc2412'!B8*W9/1000 -> 0 | O9: =+'lc2501'!B8*W9/1000 -> 0 | P9: 0 | Q9: 0 | S9: =+AVERAGE(C9:O9) -> 14.482462 | T9: 0 | U9: 0 | W9: 0.16 | Y9: =+'lc2401'!G8 -> 113750 | Z9: =+'lc2402'!G8 -> 6118 | AA9: =+'lc2403'!G8 -> 3297 | AB9: =+'lc2404'!G8 -> 4205 | AC9: =+'lc2405'!G8 -> 5748 | AD9: =+'lc2406'!G8 -> 3863 | AE9: =+'lc2407'!G8 -> 59678 | AF9: =+'lc2408'!G8 -> 5684 | AG9: =+'lc2409'!G8 -> 9771 | AH9: =+'lc2410'!G8 -> 0 | AI9: =+'lc2411'!G8 -> 0 | AJ9: =+'lc2412'!G8 -> 0 | AK9: =+'lc2501'!G8 -> 0 | AO9: =+SUM(Y9:AL9) -> 212114 | AP9: =+AO9/AO8-1 -> 0.04058045
B10: 45247 | C10: =+'lc2401'!B9*W10/1000 -> 22.08 | D10: =+'lc2402'!B9*W10/1000 -> 21.344 | E10: =+'lc2403'!B9*W10/1000 -> 21 | F10: =+'lc2404'!B9*W10/1000 -> 20.856 | G10: =+'lc2405'!B9*W10/1000 -> 20.752 | H10: =+'lc2406'!B9*W10/1000 -> 20.464 | I10: =+'lc2407'!B9*W10/1000 -> 20.32 | J10: =+'lc2408'!B9*W10/1000 -> 20.136 | K10: =+'lc2409'!B9*W10/1000 -> 19.888 | L10: =+'lc2410'!B9*W10/1000 -> 0 | M10: =+'lc2411'!B9*W10/1000 -> 0 | N10: =+'lc2412'!B9*W10/1000 -> 0 | O10: =+'lc2501'!B9*W10/1000 -> 0 | P10: 0 | Q10: 0 | S10: =+AVERAGE(C10:O10) -> 14.372308 | T10: 0 | U10: 0 | W10: 0.16 | Y10: =+'lc2401'!G9 -> 113625 | Z10: =+'lc2402'!G9 -> 5920 | AA10: =+'lc2403'!G9 -> 3310 | AB10: =+'lc2404'!G9 -> 4508 | AC10: =+'lc2405'!G9 -> 5846 | AD10: =+'lc2406'!G9 -> 3865 | AE10: =+'lc2407'!G9 -> 60858 | AF10: =+'lc2408'!G9 -> 5686 | AG10: =+'lc2409'!G9 -> 9598 | AH10: =+'lc2410'!G9 -> 0 | AI10: =+'lc2411'!G9 -> 0 | AJ10: =+'lc2412'!G9 -> 0 | AK10: =+'lc2501'!G9 -> 0 | AO10: =+SUM(Y10:AL10) -> 213216 | AP10: =+AO10/AO9-1 -> 0.0051953195
B11: 45250 | C11: =+'lc2401'!B10*W11/1000 -> 21.952 | D11: =+'lc2402'!B10*W11/1000 -> 21.104 | E11: =+'lc2403'!B10*W11/1000 -> 20.584 | F11: =+'lc2404'!B10*W11/1000 -> 20.264 | G11: =+'lc2405'!B10*W11/1000 -> 20 | H11: =+'lc2406'!B10*W11/1000 -> 19.704 | I11: =+'lc2407'!B10*W11/1000 -> 19.584 | J11: =+'lc2408'!B10*W11/1000 -> 19.56 | K11: =+'lc2409'!B10*W11/1000 -> 19.432 | L11: =+'lc2410'!B10*W11/1000 -> 0 | M11: =+'lc2411'!B10*W11/1000 -> 0 | N11: =+'lc2412'!B10*W11/1000 -> 0 | O11: =+'lc2501'!B10*W11/1000 -> 0 | P11: 0 | Q11: 0 | S11: =+AVERAGE(C11:O11) -> 14.014154 | T11: 0 | U11: 0 | W11: 0.16 | Y11: =+'lc2401'!G10 -> 117451 | Z11: =+'lc2402'!G10 -> 5875 | AA11: =+'lc2403'!G10 -> 3393 | AB11: =+'lc2404'!G10 -> 4289 | AC11: =+'lc2405'!G10 -> 6229 | AD11: =+'lc2406'!G10 -> 3844 | AE11: =+'lc2407'!G10 -> 64639 | AF11: =+'lc2408'!G10 -> 5526 | AG11: =+'lc2409'!G10 -> 9550 | AH11: =+'lc2410'!G10 -> 0 | AI11: =+'lc2411'!G10 -> 0 | AJ11: =+'lc2412'!G10 -> 0 | AK11: =+'lc2501'!G10 -> 0 | AO11: =+SUM(Y11:AL11) -> 220796 | AP11: =+AO11/AO10-1 -> 0.035550803
B12: 45251 | C12: =+'lc2401'!B11*W12/1000 -> 21.168 | D12: =+'lc2402'!B11*W12/1000 -> 20.44 | E12: =+'lc2403'!B11*W12/1000 -> 20.064 | F12: =+'lc2404'!B11*W12/1000 -> 19.896 | G12: =+'lc2405'!B11*W12/1000 -> 19.696 | H12: =+'lc2406'!B11*W12/1000 -> 19.48 | I12: =+'lc2407'!B11*W12/1000 -> 19.392 | J12: =+'lc2408'!B11*W12/1000 -> 19.392 | K12: =+'lc2409'!B11*W12/1000 -> 19.28 | L12: =+'lc2410'!B11*W12/1000 -> 0 | M12: =+'lc2411'!B11*W12/1000 -> 0 | N12: =+'lc2412'!B11*W12/1000 -> 0 | O12: =+'lc2501'!B11*W12/1000 -> 0 | P12: 0 | Q12: 0 | S12: =+AVERAGE(C12:O12) -> 13.754462 | T12: 0 | U12: 0 | W12: 0.16 | Y12: =+'lc2401'!G11 -> 119970 | Z12: =+'lc2402'!G11 -> 5781 | AA12: =+'lc2403'!G11 -> 3548 | AB12: =+'lc2404'!G11 -> 4282 | AC12: =+'lc2405'!G11 -> 6303 | AD12: =+'lc2406'!G11 -> 3872 | AE12: =+'lc2407'!G11 -> 67378 | AF12: =+'lc2408'!G11 -> 6065 | AG12: =+'lc2409'!G11 -> 9887 | AH12: =+'lc2410'!G11 -> 0 | AI12: =+'lc2411'!G11 -> 0 | AJ12: =+'lc2412'!G11 -> 0 | AK12: =+'lc2501'!G11 -> 0 | AO12: =+SUM(Y12:AL12) -> 227086 | AP12: =+AO12/AO11-1 -> 0.028487835
B13: 45252 | C13: =+'lc2401'!B12*W13/1000 -> 19.952 | D13: =+'lc2402'!B12*W13/1000 -> 19.184 | E13: =+'lc2403'!B12*W13/1000 -> 18.864 | F13: =+'lc2404'!B12*W13/1000 -> 18.864 | G13: =+'lc2405'!B12*W13/1000 -> 18.664 | H13: =+'lc2406'!B12*W13/1000 -> 18.44 | I13: =+'lc2407'!B12*W13/1000 -> 18.424 | J13: =+'lc2408'!B12*W13/1000 -> 18.4 | K13: =+'lc2409'!B12*W13/1000 -> 18.4 | L13: =+'lc2410'!B12*W13/1000 -> 0 | M13: =+'lc2411'!B12*W13/1000 -> 0 | N13: =+'lc2412'!B12*W13/1000 -> 0 | O13: =+'lc2501'!B12*W13/1000 -> 0 | P13: 0 | Q13: 0 | S13: =+AVERAGE(C13:O13) -> 13.014769 | T13: 0 | U13: 0 | W13: 0.16 | Y13: =+'lc2401'!G12 -> 117807 | Z13: =+'lc2402'!G12 -> 5793 | AA13: =+'lc2403'!G12 -> 3822 | AB13: =+'lc2404'!G12 -> 4137 | AC13: =+'lc2405'!G12 -> 6568 | AD13: =+'lc2406'!G12 -> 4026 | AE13: =+'lc2407'!G12 -> 72059 | AF13: =+'lc2408'!G12 -> 6662 | AG13: =+'lc2409'!G12 -> 10645 | AH13: =+'lc2410'!G12 -> 0 | AI13: =+'lc2411'!G12 -> 0 | AJ13: =+'lc2412'!G12 -> 0 | AK13: =+'lc2501'!G12 -> 0 | AO13: =+SUM(Y13:AL13) -> 231519 | AP13: =+AO13/AO12-1 -> 0.019521239
B14: 45253 | C14: =+'lc2401'!B13*W14/1000 -> 19.968 | D14: =+'lc2402'!B13*W14/1000 -> 19.136 | E14: =+'lc2403'!B13*W14/1000 -> 18.864 | F14: =+'lc2404'!B13*W14/1000 -> 18.64 | G14: =+'lc2405'!B13*W14/1000 -> 18.456 | H14: =+'lc2406'!B13*W14/1000 -> 18.208 | I14: =+'lc2407'!B13*W14/1000 -> 18.208 | J14: =+'lc2408'!B13*W14/1000 -> 18.264 | K14: =+'lc2409'!B13*W14/1000 -> 18.16 | L14: =+'lc2410'!B13*W14/1000 -> 0 | M14: =+'lc2411'!B13*W14/1000 -> 0 | N14: =+'lc2412'!B13*W14/1000 -> 0 | O14: =+'lc2501'!B13*W14/1000 -> 0 | P14: 0 | Q14: 0 | S14: =+AVERAGE(C14:O14) -> 12.915692 | T14: 0 | U14: 0 | W14: 0.16 | Y14: =+'lc2401'!G13 -> 115316 | Z14: =+'lc2402'!G13 -> 6045 | AA14: =+'lc2403'!G13 -> 3830 | AB14: =+'lc2404'!G13 -> 4055 | AC14: =+'lc2405'!G13 -> 6694 | AD14: =+'lc2406'!G13 -> 4060 | AE14: =+'lc2407'!G13 -> 74096 | AF14: =+'lc2408'!G13 -> 6626 | AG14: =+'lc2409'!G13 -> 10959 | AH14: =+'lc2410'!G13 -> 0 | AI14: =+'lc2411'!G13 -> 0 | AJ14: =+'lc2412'!G13 -> 0 | AK14: =+'lc2501'!G13 -> 0 | AO14: =+SUM(Y14:AL14) -> 231681 | AP14: =+AO14/AO13-1 -> 0.00069972659
B15: 45254 | C15: =+'lc2401'!B14*W15/1000 -> 19.848 | D15: =+'lc2402'!B14*W15/1000 -> 19.056 | E15: =+'lc2403'!B14*W15/1000 -> 18.704 | F15: =+'lc2404'!B14*W15/1000 -> 18.68 | G15: =+'lc2405'!B14*W15/1000 -> 18.6 | H15: =+'lc2406'!B14*W15/1000 -> 18.488 | I15: =+'lc2407'!B14*W15/1000 -> 18.376 | J15: =+'lc2408'!B14*W15/1000 -> 18.384 | K15: =+'lc2409'!B14*W15/1000 -> 18.256 | L15: =+'lc2410'!B14*W15/1000 -> 18.104 | M15: =+'lc2411'!B14*W15/1000 -> 17.928 | N15: =+'lc2412'!B14*W15/1000 -> 0 | O15: =+'lc2501'!B14*W15/1000 -> 0 | P15: 0 | Q15: 0 | S15: =+AVERAGE(C15:O15) -> 15.724923 | T15: 0 | U15: 0 | W15: 0.16 | Y15: =+'lc2401'!G14 -> 121691 | Z15: =+'lc2402'!G14 -> 6327 | AA15: =+'lc2403'!G14 -> 4409 | AB15: =+'lc2404'!G14 -> 4498 | AC15: =+'lc2405'!G14 -> 6910 | AD15: =+'lc2406'!G14 -> 4141 | AE15: =+'lc2407'!G14 -> 77344 | AF15: =+'lc2408'!G14 -> 6395 | AG15: =+'lc2409'!G14 -> 10718 | AH15: =+'lc2410'!G14 -> 4499 | AI15: =+'lc2411'!G14 -> 2325 | AJ15: =+'lc2412'!G14 -> 0 | AK15: =+'lc2501'!G14 -> 0 | AO15: =+SUM(Y15:AL15) -> 249257 | AP15: =+AO15/AO14-1 -> 0.075862932
B16: 45257 | C16: =+'lc2401'!B15*W16/1000 -> 18.664 | D16: =+'lc2402'!B15*W16/1000 -> 17.88 | E16: =+'lc2403'!B15*W16/1000 -> 17.584 | F16: =+'lc2404'!B15*W16/1000 -> 17.512 | G16: =+'lc2405'!B15*W16/1000 -> 17.376 | H16: =+'lc2406'!B15*W16/1000 -> 17.32 | I16: =+'lc2407'!B15*W16/1000 -> 17.232 | J16: =+'lc2408'!B15*W16/1000 -> 17.272 | K16: =+'lc2409'!B15*W16/1000 -> 17.168 | L16: =+'lc2410'!B15*W16/1000 -> 16.992 | M16: =+'lc2411'!B15*W16/1000 -> 16.832 | N16: =+'lc2412'!B15*W16/1000 -> 0 | O16: =+'lc2501'!B15*W16/1000 -> 0 | P16: 0 | Q16: 0 | S16: =+AVERAGE(C16:O16) -> 14.756308 | T16: =+#REF!*'Curvas Futuros'!W16/1000 -> #REF! | U16: =+#REF!*'Curvas Futuros'!W16/1000 -> #REF! | W16: 0.16 | Y16: =+'lc2401'!G15 -> 131929 | Z16: =+'lc2402'!G15 -> 6638 | AA16: =+'lc2403'!G15 -> 5833 | AB16: =+'lc2404'!G15 -> 5169 | AC16: =+'lc2405'!G15 -> 7599 | AD16: =+'lc2406'!G15 -> 4057 | AE16: =+'lc2407'!G15 -> 87321 | AF16: =+'lc2408'!G15 -> 6445 | AG16: =+'lc2409'!G15 -> 11526 | AH16: =+'lc2410'!G15 -> 4627 | AI16: =+'lc2411'!G15 -> 2800 | AJ16: =+'lc2412'!G15 -> 0 | AK16: =+'lc2501'!G15 -> 0 | AO16: =+SUM(Y16:AL16) -> 273944 | AP16: =+AO16/AO15-1 -> 0.099042354
B17: 45258 | C17: =+'lc2401'!B16*W17/1000 -> 18.112 | D17: =+'lc2402'!B16*W17/1000 -> 17.52 | E17: =+'lc2403'!B16*W17/1000 -> 17.416 | F17: =+'lc2404'!B16*W17/1000 -> 17.576 | G17: =+'lc2405'!B16*W17/1000 -> 17.608 | H17: =+'lc2406'!B16*W17/1000 -> 17.592 | I17: =+'lc2407'!B16*W17/1000 -> 17.528 | J17: =+'lc2408'!B16*W17/1000 -> 17.528 | K17: =+'lc2409'!B16*W17/1000 -> 17.408 | L17: =+'lc2410'!B16*W17/1000 -> 17.28 | M17: =+'lc2411'!B16*W17/1000 -> 17.088 | N17: =+'lc2412'!B16*W17/1000 -> 0 | O17: =+'lc2501'!B16*W17/1000 -> 0 | P17: 0 | Q17: 0 | S17: =+AVERAGE(C17:O17) -> 14.819692 | T17: =+#REF!*'Curvas Futuros'!W17/1000 -> #REF! | U17: =+#REF!*'Curvas Futuros'!W17/1000 -> #REF! | W17: 0.16 | Y17: =+'lc2401'!G16 -> 122822 | Z17: =+'lc2402'!G16 -> 7186 | AA17: =+'lc2403'!G16 -> 7388 | AB17: =+'lc2404'!G16 -> 6575 | AC17: =+'lc2405'!G16 -> 8773 | AD17: =+'lc2406'!G16 -> 4162 | AE17: =+'lc2407'!G16 -> 93278 | AF17: =+'lc2408'!G16 -> 6471 | AG17: =+'lc2409'!G16 -> 12046 | AH17: =+'lc2410'!G16 -> 4742 | AI17: =+'lc2411'!G16 -> 2937 | AJ17: =+'lc2412'!G16 -> 0 | AK17: =+'lc2501'!G16 -> 0 | AO17: =+SUM(Y17:AL17) -> 276380 | AP17: =+AO17/AO16-1 -> 0.0088923284
B18: 45259 | C18: =+'lc2401'!B17*W18/1000 -> 17.576 | D18: =+'lc2402'!B17*W18/1000 -> 17.368 | E18: =+'lc2403'!B17*W18/1000 -> 17.336 | F18: =+'lc2404'!B17*W18/1000 -> 17.808 | G18: =+'lc2405'!B17*W18/1000 -> 17.824 | H18: =+'lc2406'!B17*W18/1000 -> 17.848 | I18: =+'lc2407'!B17*W18/1000 -> 17.856 | J18: =+'lc2408'!B17*W18/1000 -> 17.8 | K18: =+'lc2409'!B17*W18/1000 -> 17.688 | L18: =+'lc2410'!B17*W18/1000 -> 17.536 | M18: =+'lc2411'!B17*W18/1000 -> 17.416 | N18: =+'lc2412'!B17*W18/1000 -> 0 | O18: =+'lc2501'!B17*W18/1000 -> 0 | P18: 0 | Q18: 0 | S18: =+AVERAGE(C18:O18) -> 14.927385 | T18: =+#REF!*'Curvas Futuros'!W18/1000 -> #REF! | U18: =+#REF!*'Curvas Futuros'!W18/1000 -> #REF! | W18: 0.16 | Y18: =+'lc2401'!G17 -> 140181 | Z18: =+'lc2402'!G17 -> 9534 | AA18: =+'lc2403'!G17 -> 9844 | AB18: =+'lc2404'!G17 -> 9537 | AC18: =+'lc2405'!G17 -> 10466 | AD18: =+'lc2406'!G17 -> 4338 | AE18: =+'lc2407'!G17 -> 105471 | AF18: =+'lc2408'!G17 -> 6213 | AG18: =+'lc2409'!G17 -> 12213 | AH18: =+'lc2410'!G17 -> 4802 | AI18: =+'lc2411'!G17 -> 2894 | AJ18: =+'lc2412'!G17 -> 0 | AK18: =+'lc2501'!G17 -> 0 | AO18: =+SUM(Y18:AL18) -> 315493 | AP18: =+AO18/AO17-1 -> 0.14151892
B19: 45260 | C19: =+'lc2401'!B18*W19/1000 -> 16.992 | D19: =+'lc2402'!B18*W19/1000 -> 16.816 | E19: =+'lc2403'!B18*W19/1000 -> 16.768 | F19: =+'lc2404'!B18*W19/1000 -> 17.264 | G19: =+'lc2405'!B18*W19/1000 -> 17.232 | H19: =+'lc2406'!B18*W19/1000 -> 17.28 | I19: =+'lc2407'!B18*W19/1000 -> 17.224 | J19: =+'lc2408'!B18*W19/1000 -> 17.296 | K19: =+'lc2409'!B18*W19/1000 -> 17.216 | L19: =+'lc2410'!B18*W19/1000 -> 17.12 | M19: =+'lc2411'!B18*W19/1000 -> 16.984 | N19: =+'lc2412'!B18*W19/1000 -> 0 | O19: =+'lc2501'!B18*W19/1000 -> 0 | P19: 0 | Q19: 0 | S19: =+AVERAGE(C19:O19) -> 14.476308 | T19: =+#REF!*'Curvas Futuros'!W19/1000 -> #REF! | U19: =+#REF!*'Curvas Futuros'!W19/1000 -> #REF! | W19: 0.16 | Y19: =+'lc2401'!G18 -> 145373 | Z19: =+'lc2402'!G18 -> 9965 | AA19: =+'lc2403'!G18 -> 10313 | AB19: =+'lc2404'!G18 -> 9975 | AC19: =+'lc2405'!G18 -> 10999 | AD19: =+'lc2406'!G18 -> 4341 | AE19: =+'lc2407'!G18 -> 111186 | AF19: =+'lc2408'!G18 -> 6386 | AG19: =+'lc2409'!G18 -> 12492 | AH19: =+'lc2410'!G18 -> 4777 | AI19: =+'lc2411'!G18 -> 3129 | AJ19: =+'lc2412'!G18 -> 0 | AK19: =+'lc2501'!G18 -> 0 | AO19: =+SUM(Y19:AL19) -> 328936 | AP19: =+AO19/AO18-1 -> 0.042609503
B20: 45261 | C20: =+'lc2401'!B19*W20/1000 -> 16.28 | D20: =+'lc2402'!B19*W20/1000 -> 16.032 | E20: =+'lc2403'!B19*W20/1000 -> 16.016 | F20: =+'lc2404'!B19*W20/1000 -> 16.68 | G20: =+'lc2405'!B19*W20/1000 -> 16.696 | H20: =+'lc2406'!B19*W20/1000 -> 16.688 | I20: =+'lc2407'!B19*W20/1000 -> 16.728 | J20: =+'lc2408'!B19*W20/1000 -> 16.704 | K20: =+'lc2409'!B19*W20/1000 -> 16.672 | L20: =+'lc2410'!B19*W20/1000 -> 16.616 | M20: =+'lc2411'!B19*W20/1000 -> 16.464 | N20: =+'lc2412'!B19*W20/1000 -> 0 | O20: =+'lc2501'!B19*W20/1000 -> 0 | P20: 0 | Q20: 0 | S20: =+AVERAGE(C20:O20) -> 13.967385 | T20: =+#REF!*'Curvas Futuros'!W20/1000 -> #REF! | U20: =+#REF!*'Curvas Futuros'!W20/1000 -> #REF! | W20: 0.16 | Y20: =+'lc2401'!G19 -> 135708 | Z20: =+'lc2402'!G19 -> 12282 | AA20: =+'lc2403'!G19 -> 12749 | AB20: =+'lc2404'!G19 -> 12287 | AC20: =+'lc2405'!G19 -> 12033 | AD20: =+'lc2406'!G19 -> 4607 | AE20: =+'lc2407'!G19 -> 114139 | AF20: =+'lc2408'!G19 -> 6778 | AG20: =+'lc2409'!G19 -> 13157 | AH20: =+'lc2410'!G19 -> 4755 | AI20: =+'lc2411'!G19 -> 3608 | AJ20: =+'lc2412'!G19 -> 0 | AK20: =+'lc2501'!G19 -> 0 | AO20: =+SUM(Y20:AL20) -> 332103 | AP20: =+AO20/AO19-1 -> 0.0096280127
B21: 45264 | C21: =+'lc2401'!B20*W21/1000 -> 15.416 | D21: =+'lc2402'!B20*W21/1000 -> 15.16 | E21: =+'lc2403'!B20*W21/1000 -> 15.128 | F21: =+'lc2404'!B20*W21/1000 -> 15.6 | G21: =+'lc2405'!B20*W21/1000 -> 15.6 | H21: =+'lc2406'!B20*W21/1000 -> 15.6 | I21: =+'lc2407'!B20*W21/1000 -> 15.56 | J21: =+'lc2408'!B20*W21/1000 -> 15.656 | K21: =+'lc2409'!B20*W21/1000 -> 15.568 | L21: =+'lc2410'!B20*W21/1000 -> 15.488 | M21: =+'lc2411'!B20*W21/1000 -> 15.368 | N21: =+'lc2412'!B20*W21/1000 -> 0 | O21: =+'lc2501'!B20*W21/1000 -> 0 | P21: 0 | Q21: 0 | S21: =+AVERAGE(C21:O21) -> 13.088 | T21: =+#REF!*'Curvas Futuros'!W21/1000 -> #REF! | U21: =+#REF!*'Curvas Futuros'!W21/1000 -> #REF! | W21: 0.16 | Y21: =+'lc2401'!G20 -> 145648 | Z21: =+'lc2402'!G20 -> 15204 | AA21: =+'lc2403'!G20 -> 14212 | AB21: =+'lc2404'!G20 -> 16676 | AC21: =+'lc2405'!G20 -> 13121 | AD21: =+'lc2406'!G20 -> 4864 | AE21: =+'lc2407'!G20 -> 128879 | AF21: =+'lc2408'!G20 -> 7433 | AG21: =+'lc2409'!G20 -> 13411 | AH21: =+'lc2410'!G20 -> 4773 | AI21: =+'lc2411'!G20 -> 4562 | AJ21: =+'lc2412'!G20 -> 0 | AK21: =+'lc2501'!G20 -> 0 | AO21: =+SUM(Y21:AL21) -> 368783 | AP21: =+AO21/AO20-1 -> 0.11044766
B22: 45265 | C22: =+'lc2401'!B21*W22/1000 -> 14.888 | D22: =+'lc2402'!B21*W22/1000 -> 14.088 | E22: =+'lc2403'!B21*W22/1000 -> 14.112 | F22: =+'lc2404'!B21*W22/1000 -> 14.656 | G22: =+'lc2405'!B21*W22/1000 -> 14.568 | H22: =+'lc2406'!B21*W22/1000 -> 14.616 | I22: =+'lc2407'!B21*W22/1000 -> 14.528 | J22: =+'lc2408'!B21*W22/1000 -> 14.608 | K22: =+'lc2409'!B21*W22/1000 -> 14.488 | L22: =+'lc2410'!B21*W22/1000 -> 14.384 | M22: =+'lc2411'!B21*W22/1000 -> 14.728 | N22: =+'lc2412'!B21*W22/1000 -> 0 | O22: =+'lc2501'!B21*W22/1000 -> 0 | P22: 0 | Q22: 0 | S22: =+AVERAGE(C22:O22) -> 12.281846 | T22: =+#REF!*'Curvas Futuros'!W22/1000 -> #REF! | U22: =+#REF!*'Curvas Futuros'!W22/1000 -> #REF! | W22: 0.16 | Y22: =+'lc2401'!G21 -> 150052 | Z22: =+'lc2402'!G21 -> 19643 | AA22: =+'lc2403'!G21 -> 14505 | AB22: =+'lc2404'!G21 -> 17394 | AC22: =+'lc2405'!G21 -> 13499 | AD22: =+'lc2406'!G21 -> 5072 | AE22: =+'lc2407'!G21 -> 138614 | AF22: =+'lc2408'!G21 -> 7278 | AG22: =+'lc2409'!G21 -> 13364 | AH22: =+'lc2410'!G21 -> 4956 | AI22: =+'lc2411'!G21 -> 5254 | AJ22: =+'lc2412'!G21 -> 0 | AK22: =+'lc2501'!G21 -> 0 | AO22: =+SUM(Y22:AL22) -> 389631 | AP22: =+AO22/AO21-1 -> 0.05653189
B23: 45266 | C23: =+'lc2401'!B22*W23/1000 -> 14.792 | D23: =+'lc2402'!B22*W23/1000 -> 14.36 | E23: =+'lc2403'!B22*W23/1000 -> 14.416 | F23: =+'lc2404'!B22*W23/1000 -> 14.944 | G23: =+'lc2405'!B22*W23/1000 -> 14.96 | H23: =+'lc2406'!B22*W23/1000 -> 14.904 | I23: =+'lc2407'!B22*W23/1000 -> 14.944 | J23: =+'lc2408'!B22*W23/1000 -> 14.936 | K23: =+'lc2409'!B22*W23/1000 -> 14.88 | L23: =+'lc2410'!B22*W23/1000 -> 14.784 | M23: =+'lc2411'!B22*W23/1000 -> 14.744 | N23: =+'lc2412'!B22*W23/1000 -> 0 | O23: =+'lc2501'!B22*W23/1000 -> 0 | P23: 0 | Q23: 0 | S23: =+AVERAGE(C23:O23) -> 12.512615 | T23: =+#REF!*'Curvas Futuros'!W23/1000 -> #REF! | U23: =+#REF!*'Curvas Futuros'!W23/1000 -> #REF! | W23: 0.16 | Y23: =+'lc2401'!G22 -> 128963 | Z23: =+'lc2402'!G22 -> 21976 | AA23: =+'lc2403'!G22 -> 17531 | AB23: =+'lc2404'!G22 -> 21030 | AC23: =+'lc2405'!G22 -> 14396 | AD23: =+'lc2406'!G22 -> 5136 | AE23: =+'lc2407'!G22 -> 148646 | AF23: =+'lc2408'!G22 -> 7504 | AG23: =+'lc2409'!G22 -> 13289 | AH23: =+'lc2410'!G22 -> 5036 | AI23: =+'lc2411'!G22 -> 5389 | AJ23: =+'lc2412'!G22 -> 0 | AK23: =+'lc2501'!G22 -> 0 | AO23: =+SUM(Y23:AL23) -> 388896 | AP23: =+AO23/AO22-1 -> -0.0018864002
B24: 45267 | C24: =+'lc2401'!B23*W24/1000 -> 15.296 | D24: =+'lc2402'!B23*W24/1000 -> 14.816 | E24: =+'lc2403'!B23*W24/1000 -> 14.808 | F24: =+'lc2404'!B23*W24/1000 -> 15.32 | G24: =+'lc2405'!B23*W24/1000 -> 15.312 | H24: =+'lc2406'!B23*W24/1000 -> 15.328 | I24: =+'lc2407'!B23*W24/1000 -> 15.32 | J24: =+'lc2408'!B23*W24/1000 -> 15.368 | K24: =+'lc2409'!B23*W24/1000 -> 15.24 | L24: =+'lc2410'!B23*W24/1000 -> 15.128 | M24: =+'lc2411'!B23*W24/1000 -> 15.056 | N24: =+'lc2412'!B23*W24/1000 -> 0 | O24: =+'lc2501'!B23*W24/1000 -> 0 | P24: 0 | Q24: 0 | S24: =+AVERAGE(C24:O24) -> 12.845538 | T24: =+#REF!*'Curvas Futuros'!W24/1000 -> #REF! | U24: =+#REF!*'Curvas Futuros'!W24/1000 -> #REF! | W24: 0.16 | Y24: =+'lc2401'!G23 -> 124068 | Z24: =+'lc2402'!G23 -> 25035 | AA24: =+'lc2403'!G23 -> 17452 | AB24: =+'lc2404'!G23 -> 23101 | AC24: =+'lc2405'!G23 -> 14736 | AD24: =+'lc2406'!G23 -> 5178 | AE24: =+'lc2407'!G23 -> 165720 | AF24: =+'lc2408'!G23 -> 7523 | AG24: =+'lc2409'!G23 -> 13362 | AH24: =+'lc2410'!G23 -> 4995 | AI24: =+'lc2411'!G23 -> 5496 | AJ24: =+'lc2412'!G23 -> 0 | AK24: =+'lc2501'!G23 -> 0 | AO24: =+SUM(Y24:AL24) -> 406666 | AP24: =+AO24/AO23-1 -> 0.04569345
B25: 45268 | C25: =+'lc2401'!B24*W25/1000 -> 16.496 | D25: =+'lc2402'!B24*W25/1000 -> 15.864 | E25: =+'lc2403'!B24*W25/1000 -> 15.824 | F25: =+'lc2404'!B24*W25/1000 -> 16.352 | G25: =+'lc2405'!B24*W25/1000 -> 16.352 | H25: =+'lc2406'!B24*W25/1000 -> 16.392 | I25: =+'lc2407'!B24*W25/1000 -> 16.368 | J25: =+'lc2408'!B24*W25/1000 -> 16.504 | K25: =+'lc2409'!B24*W25/1000 -> 16.312 | L25: =+'lc2410'!B24*W25/1000 -> 16.216 | M25: =+'lc2411'!B24*W25/1000 -> 16.136 | N25: =+'lc2412'!B24*W25/1000 -> 0 | O25: =+'lc2501'!B24*W25/1000 -> 0 | P25: 0 | Q25: 0 | S25: =+AVERAGE(C25:O25) -> 13.755077 | T25: =+#REF!*'Curvas Futuros'!W25/1000 -> #REF! | U25: =+#REF!*'Curvas Futuros'!W25/1000 -> #REF! | W25: 0.16 | Y25: =+'lc2401'!G24 -> 126990 | Z25: =+'lc2402'!G24 -> 24010 | AA25: =+'lc2403'!G24 -> 16954 | AB25: =+'lc2404'!G24 -> 22664 | AC25: =+'lc2405'!G24 -> 14000 | AD25: =+'lc2406'!G24 -> 5147 | AE25: =+'lc2407'!G24 -> 158315 | AF25: =+'lc2408'!G24 -> 7468 | AG25: =+'lc2409'!G24 -> 12636 | AH25: =+'lc2410'!G24 -> 4812 | AI25: =+'lc2411'!G24 -> 7421 | AJ25: =+'lc2412'!G24 -> 0 | AK25: =+'lc2501'!G24 -> 0 | AO25: =+SUM(Y25:AL25) -> 400417 | AP25: =+AO25/AO24-1 -> -0.015366419
B26: 45271 | C26: =+'lc2401'!B25*W26/1000 -> 15.832 | D26: =+'lc2402'!B25*W26/1000 -> 15.336 | E26: =+'lc2403'!B25*W26/1000 -> 15.296 | F26: =+'lc2404'!B25*W26/1000 -> 15.704 | G26: =+'lc2405'!B25*W26/1000 -> 15.576 | H26: =+'lc2406'!B25*W26/1000 -> 15.448 | I26: =+'lc2407'!B25*W26/1000 -> 15.488 | J26: =+'lc2408'!B25*W26/1000 -> 15.536 | K26: =+'lc2409'!B25*W26/1000 -> 15.456 | L26: =+'lc2410'!B25*W26/1000 -> 15.36 | M26: =+'lc2411'!B25*W26/1000 -> 15.304 | N26: =+'lc2412'!B25*W26/1000 -> 0 | O26: =+'lc2501'!B25*W26/1000 -> 0 | P26: 0 | Q26: 0 | S26: =+AVERAGE(C26:O26) -> 13.102769 | T26: =+#REF!*'Curvas Futuros'!W26/1000 -> #REF! | U26: =+#REF!*'Curvas Futuros'!W26/1000 -> #REF! | W26: 0.16 | Y26: =+'lc2401'!G25 -> 54850 | Z26: =+'lc2402'!G25 -> 18047 | AA26: =+'lc2403'!G25 -> 15965 | AB26: =+'lc2404'!G25 -> 18423 | AC26: =+'lc2405'!G25 -> 10667 | AD26: =+'lc2406'!G25 -> 4265 | AE26: =+'lc2407'!G25 -> 156695 | AF26: =+'lc2408'!G25 -> 6611 | AG26: =+'lc2409'!G25 -> 11665 | AH26: =+'lc2410'!G25 -> 4359 | AI26: =+'lc2411'!G25 -> 6493 | AJ26: =+'lc2412'!G25 -> 0 | AK26: =+'lc2501'!G25 -> 0 | AO26: =+SUM(Y26:AL26) -> 308040 | AP26: =+AO26/AO25-1 -> -0.23070199
B27: 45272 | C27: =+'lc2401'!B26*W27/1000 -> 15.52 | D27: =+'lc2402'!B26*W27/1000 -> 14.968 | E27: =+'lc2403'!B26*W27/1000 -> 14.744 | F27: =+'lc2404'!B26*W27/1000 -> 15.192 | G27: =+'lc2405'!B26*W27/1000 -> 15.032 | H27: =+'lc2406'!B26*W27/1000 -> 15.16 | I27: =+'lc2407'!B26*W27/1000 -> 14.896 | J27: =+'lc2408'!B26*W27/1000 -> 15.208 | K27: =+'lc2409'!B26*W27/1000 -> 15.04 | L27: =+'lc2410'!B26*W27/1000 -> 14.976 | M27: =+'lc2411'!B26*W27/1000 -> 14.872 | N27: =+'lc2412'!B26*W27/1000 -> 0 | O27: =+'lc2501'!B26*W27/1000 -> 0 | P27: 0 | Q27: 0 | S27: =+AVERAGE(C27:O27) -> 12.739077 | T27: =+#REF!*'Curvas Futuros'!W27/1000 -> #REF! | U27: =+#REF!*'Curvas Futuros'!W27/1000 -> #REF! | W27: 0.16 | Y27: =+'lc2401'!G26 -> 52972 | Z27: =+'lc2402'!G26 -> 18310 | AA27: =+'lc2403'!G26 -> 16581 | AB27: =+'lc2404'!G26 -> 18082 | AC27: =+'lc2405'!G26 -> 9333 | AD27: =+'lc2406'!G26 -> 4987 | AE27: =+'lc2407'!G26 -> 172604 | AF27: =+'lc2408'!G26 -> 6915 | AG27: =+'lc2409'!G26 -> 11917 | AH27: =+'lc2410'!G26 -> 4575 | AI27: =+'lc2411'!G26 -> 7420 | AJ27: =+'lc2412'!G26 -> 0 | AK27: =+'lc2501'!G26 -> 0 | AO27: =+SUM(Y27:AL27) -> 323696 | AP27: =+AO27/AO26-1 -> 0.050824568
B28: 45273 | C28: =+'lc2401'!B27*W28/1000 -> 17.368 | D28: =+'lc2402'!B27*W28/1000 -> 17.064 | E28: =+'lc2403'!B27*W28/1000 -> 16.496 | F28: =+'lc2404'!B27*W28/1000 -> 17.392 | G28: =+'lc2405'!B27*W28/1000 -> 16.808 | H28: =+'lc2406'!B27*W28/1000 -> 17.2 | I28: =+'lc2407'!B27*W28/1000 -> 16.568 | J28: =+'lc2408'!B27*W28/1000 -> 17.328 | K28: =+'lc2409'!B27*W28/1000 -> 16.76 | L28: =+'lc2410'!B27*W28/1000 -> 16.584 | M28: =+'lc2411'!B27*W28/1000 -> 16.432 | N28: =+'lc2412'!B27*W28/1000 -> 0 | O28: =+'lc2501'!B27*W28/1000 -> 0 | P28: =+'lc2501'!C27*X28/1000 -> 0 | Q28: 0 | S28: =+AVERAGE(C28:O28) -> 14.307692 | T28: =+#REF!*'Curvas Futuros'!W28/1000 -> #REF! | U28: =+#REF!*'Curvas Futuros'!W28/1000 -> #REF! | W28: 0.16 | Y28: =+'lc2401'!G27 -> 46331 | Z28: =+'lc2402'!G27 -> 19057 | AA28: =+'lc2403'!G27 -> 18067 | AB28: =+'lc2404'!G27 -> 21630 | AC28: =+'lc2405'!G27 -> 11174 | AD28: =+'lc2406'!G27 -> 4975 | AE28: =+'lc2407'!G27 -> 172000 | AF28: =+'lc2408'!G27 -> 7368 | AG28: =+'lc2409'!G27 -> 11183 | AH28: =+'lc2410'!G27 -> 4503 | AI28: =+'lc2411'!G27 -> 7285 | AJ28: =+'lc2412'!G27 -> 0 | AK28: =+'lc2501'!G27 -> 0 | AO28: =+SUM(Y28:AL28) -> 323573 | AP28: =+AO28/AO27-1 -> -0.00037998616
B29: 45274 | C29: =+'lc2401'!B28*W29/1000 -> 16.152 | D29: =+'lc2402'!B28*W29/1000 -> 15.984 | E29: =+'lc2403'!B28*W29/1000 -> 15.944 | F29: =+'lc2404'!B28*W29/1000 -> 16.464 | G29: =+'lc2405'!B28*W29/1000 -> 16.416 | H29: =+'lc2406'!B28*W29/1000 -> 16.48 | I29: =+'lc2407'!B28*W29/1000 -> 16.408 | J29: =+'lc2408'!B28*W29/1000 -> 16.52 | K29: =+'lc2409'!B28*W29/1000 -> 16.456 | L29: =+'lc2410'!B28*W29/1000 -> 16.344 | M29: =+'lc2411'!B28*W29/1000 -> 16.248 | N29: =+'lc2412'!B28*W29/1000 -> 0 | O29: =+'lc2501'!B28*W29/1000 -> 0 | P29: =+'lc2501'!C28*X29/1000 -> 0 | Q29: 0 | S29: =+AVERAGE(C29:O29) -> 13.801231 | T29: =+#REF!*'Curvas Futuros'!W29/1000 -> #REF! | U29: =+#REF!*'Curvas Futuros'!W29/1000 -> #REF! | W29: 0.16 | Y29: =+'lc2401'!G28 -> 40783 | Z29: =+'lc2402'!G28 -> 18374 | AA29: =+'lc2403'!G28 -> 16647 | AB29: =+'lc2404'!G28 -> 23590 | AC29: =+'lc2405'!G28 -> 10997 | AD29: =+'lc2406'!G28 -> 5521 | AE29: =+'lc2407'!G28 -> 161651 | AF29: =+'lc2408'!G28 -> 7431 | AG29: =+'lc2409'!G28 -> 10785 | AH29: =+'lc2410'!G28 -> 4294 | AI29: =+'lc2411'!G28 -> 7254 | AJ29: =+'lc2412'!G28 -> 0 | AK29: =+'lc2501'!G28 -> 0 | AO29: =+SUM(Y29:AL29) -> 307327 | AP29: =+AO29/AO28-1 -> -0.050208145
B30: 45275 | C30: =+'lc2401'!B29*W30/1000 -> 16.288 | D30: =+'lc2402'!B29*W30/1000 -> 16.152 | E30: =+'lc2403'!B29*W30/1000 -> 16.144 | F30: =+'lc2404'!B29*W30/1000 -> 16.776 | G30: =+'lc2405'!B29*W30/1000 -> 16.768 | H30: =+'lc2406'!B29*W30/1000 -> 16.768 | I30: =+'lc2407'!B29*W30/1000 -> 16.736 | J30: =+'lc2408'!B29*W30/1000 -> 16.848 | K30: =+'lc2409'!B29*W30/1000 -> 16.752 | L30: =+'lc2410'!B29*W30/1000 -> 16.64 | M30: =+'lc2411'!B29*W30/1000 -> 16.552 | N30: =+'lc2412'!B29*W30/1000 -> 16.744 | O30: =+'lc2501'!B29*W30/1000 -> 0 | P30: =+'lc2501'!C29*X30/1000 -> 0 | Q30: 0 | S30: =+AVERAGE(C30:O30) -> 15.320615 | T30: =+#REF!*'Curvas Futuros'!W30/1000 -> #REF! | U30: =+#REF!*'Curvas Futuros'!W30/1000 -> #REF! | W30: 0.16 | Y30: =+'lc2401'!G29 -> 36236 | Z30: =+'lc2402'!G29 -> 18204 | AA30: =+'lc2403'!G29 -> 19115 | AB30: =+'lc2404'!G29 -> 25617 | AC30: =+'lc2405'!G29 -> 11428 | AD30: =+'lc2406'!G29 -> 5583 | AE30: =+'lc2407'!G29 -> 159950 | AF30: =+'lc2408'!G29 -> 7407 | AG30: =+'lc2409'!G29 -> 10446 | AH30: =+'lc2410'!G29 -> 4338 | AI30: =+'lc2411'!G29 -> 7067 | AJ30: =+'lc2412'!G29 -> 70 | AK30: =+'lc2501'!G29 -> 0 | AO30: =+SUM(Y30:AL30) -> 305461 | AP30: =+AO30/AO29-1 -> -0.0060717086
B31: 45278 | C31: =+'lc2401'!B30*W31/1000 -> 16.096 | D31: =+'lc2402'!B30*W31/1000 -> 15.96 | E31: =+'lc2403'!B30*W31/1000 -> 15.96 | F31: =+'lc2404'!B30*W31/1000 -> 16.56 | G31: =+'lc2405'!B30*W31/1000 -> 16.512 | H31: =+'lc2406'!B30*W31/1000 -> 16.44 | I31: =+'lc2407'!B30*W31/1000 -> 16.44 | J31: =+'lc2408'!B30*W31/1000 -> 16.664 | K31: =+'lc2409'!B30*W31/1000 -> 16.592 | L31: =+'lc2410'!B30*W31/1000 -> 16.424 | M31: =+'lc2411'!B30*W31/1000 -> 16.296 | N31: =+'lc2412'!B30*W31/1000 -> 16.4 | O31: =+'lc2501'!B30*W31/1000 -> 0 | P31: =+'lc2501'!C30*X31/1000 -> 0 | Q31: 0 | S31: =+AVERAGE(C31:O31) -> 15.103385 | T31: =+#REF!*'Curvas Futuros'!W31/1000 -> #REF! | U31: =+#REF!*'Curvas Futuros'!W31/1000 -> #REF! | W31: 0.16 | Y31: =+'lc2401'!G30 -> 32722 | Z31: =+'lc2402'!G30 -> 17434 | AA31: =+'lc2403'!G30 -> 19135 | AB31: =+'lc2404'!G30 -> 25079 | AC31: =+'lc2405'!G30 -> 11639 | AD31: =+'lc2406'!G30 -> 5610 | AE31: =+'lc2407'!G30 -> 159746 | AF31: =+'lc2408'!G30 -> 7516 | AG31: =+'lc2409'!G30 -> 10263 | AH31: =+'lc2410'!G30 -> 4205 | AI31: =+'lc2411'!G30 -> 7103 | AJ31: =+'lc2412'!G30 -> 122 | AK31: =+'lc2501'!G30 -> 0 | AO31: =+SUM(Y31:AL31) -> 300574 | AP31: =+AO31/AO30-1 -> -0.015998769
B32: 45279 | C32: =+'lc2401'!B31*W32/1000 -> 15.92 | D32: =+'lc2402'!B31*W32/1000 -> 15.84 | E32: =+'lc2403'!B31*W32/1000 -> 15.856 | F32: =+'lc2404'!B31*W32/1000 -> 16.4 | G32: =+'lc2405'!B31*W32/1000 -> 16.344 | H32: =+'lc2406'!B31*W32/1000 -> 16.32 | I32: =+'lc2407'!B31*W32/1000 -> 16.304 | J32: =+'lc2408'!B31*W32/1000 -> 16.504 | K32: =+'lc2409'!B31*W32/1000 -> 16.4 | L32: =+'lc2410'!B31*W32/1000 -> 16.312 | M32: =+'lc2411'!B31*W32/1000 -> 16.256 | N32: =+'lc2412'!B31*W32/1000 -> 16.216 | O32: =+'lc2501'!B31*W32/1000 -> 0 | P32: =+'lc2501'!C31*X32/1000 -> 0 | Q32: 0 | S32: =+AVERAGE(C32:O32) -> 14.974769 | T32: =+#REF!*'Curvas Futuros'!W32/1000 -> #REF! | U32: =+#REF!*'Curvas Futuros'!W32/1000 -> #REF! | W32: 0.16 | Y32: =+'lc2401'!G31 -> 30452 | Z32: =+'lc2402'!G31 -> 16308 | AA32: =+'lc2403'!G31 -> 18696 | AB32: =+'lc2404'!G31 -> 24580 | AC32: =+'lc2405'!G31 -> 11403 | AD32: =+'lc2406'!G31 -> 5552 | AE32: =+'lc2407'!G31 -> 159563 | AF32: =+'lc2408'!G31 -> 7674 | AG32: =+'lc2409'!G31 -> 10164 | AH32: =+'lc2410'!G31 -> 4185 | AI32: =+'lc2411'!G31 -> 7171 | AJ32: =+'lc2412'!G31 -> 137 | AK32: =+'lc2501'!G31 -> 0 | AO32: =+SUM(Y32:AL32) -> 295885 | AP32: =+AO32/AO31-1 -> -0.015600152
B33: 45280 | C33: =+'lc2401'!B32*W33/1000 -> 15.6 | D33: =+'lc2402'!B32*W33/1000 -> 15.608 | E33: =+'lc2403'!B32*W33/1000 -> 15.68 | F33: =+'lc2404'!B32*W33/1000 -> 16.184 | G33: =+'lc2405'!B32*W33/1000 -> 16.208 | H33: =+'lc2406'!B32*W33/1000 -> 16.176 | I33: =+'lc2407'!B32*W33/1000 -> 16.128 | J33: =+'lc2408'!B32*W33/1000 -> 16.456 | K33: =+'lc2409'!B32*W33/1000 -> 16.376 | L33: =+'lc2410'!B32*W33/1000 -> 16.344 | M33: =+'lc2411'!B32*W33/1000 -> 16.272 | N33: =+'lc2412'!B32*W33/1000 -> 16.224 | O33: =+'lc2501'!B32*W33/1000 -> 0 | P33: =+'lc2501'!C32*X33/1000 -> 0 | Q33: 0 | S33: =+AVERAGE(C33:O33) -> 14.865846 | T33: =+#REF!*'Curvas Futuros'!W33/1000 -> #REF! | U33: =+#REF!*'Curvas Futuros'!W33/1000 -> #REF! | W33: 0.16 | Y33: =+'lc2401'!G32 -> 26757 | Z33: =+'lc2402'!G32 -> 15620 | AA33: =+'lc2403'!G32 -> 18476 | AB33: =+'lc2404'!G32 -> 24470 | AC33: =+'lc2405'!G32 -> 11307 | AD33: =+'lc2406'!G32 -> 5488 | AE33: =+'lc2407'!G32 -> 162654 | AF33: =+'lc2408'!G32 -> 7841 | AG33: =+'lc2409'!G32 -> 10089 | AH33: =+'lc2410'!G32 -> 4214 | AI33: =+'lc2411'!G32 -> 7043 | AJ33: =+'lc2412'!G32 -> 160 | AK33: =+'lc2501'!G32 -> 0 | AO33: =+SUM(Y33:AL33) -> 294119 | AP33: =+AO33/AO32-1 -> -0.0059685351
B34: 45281 | C34: =+'lc2401'!B33*W34/1000 -> 15.096 | D34: =+'lc2402'!B33*W34/1000 -> 15.112 | E34: =+'lc2403'!B33*W34/1000 -> 15.16 | F34: =+'lc2404'!B33*W34/1000 -> 15.72 | G34: =+'lc2405'!B33*W34/1000 -> 15.68 | H34: =+'lc2406'!B33*W34/1000 -> 15.688 | I34: =+'lc2407'!B33*W34/1000 -> 15.616 | J34: =+'lc2408'!B33*W34/1000 -> 16.04 | K34: =+'lc2409'!B33*W34/1000 -> 15.952 | L34: =+'lc2410'!B33*W34/1000 -> 15.912 | M34: =+'lc2411'!B33*W34/1000 -> 15.888 | N34: =+'lc2412'!B33*W34/1000 -> 15.76 | O34: =+'lc2501'!B33*W34/1000 -> 0 | P34: =+'lc2501'!C33*X34/1000 -> 0 | Q34: 0 | S34: =+AVERAGE(C34:O34) -> 14.432615 | T34: =+#REF!*'Curvas Futuros'!W34/1000 -> #REF! | U34: =+#REF!*'Curvas Futuros'!W34/1000 -> #REF! | W34: 0.16 | Y34: =+'lc2401'!G33 -> 24583 | Z34: =+'lc2402'!G33 -> 15099 | AA34: =+'lc2403'!G33 -> 19003 | AB34: =+'lc2404'!G33 -> 24746 | AC34: =+'lc2405'!G33 -> 11508 | AD34: =+'lc2406'!G33 -> 5448 | AE34: =+'lc2407'!G33 -> 158076 | AF34: =+'lc2408'!G33 -> 8132 | AG34: =+'lc2409'!G33 -> 10150 | AH34: =+'lc2410'!G33 -> 4218 | AI34: =+'lc2411'!G33 -> 7249 | AJ34: =+'lc2412'!G33 -> 197 | AK34: =+'lc2501'!G33 -> 0 | AO34: =+SUM(Y34:AL34) -> 288409 | AP34: =+AO34/AO33-1 -> -0.019413911
B35: 45282 | C35: =+'lc2401'!B34*W35/1000 -> 15.44 | D35: =+'lc2402'!B34*W35/1000 -> 15.504 | E35: =+'lc2403'!B34*W35/1000 -> 15.528 | F35: =+'lc2404'!B34*W35/1000 -> 16.176 | G35: =+'lc2405'!B34*W35/1000 -> 16.168 | H35: =+'lc2406'!B34*W35/1000 -> 16.184 | I35: =+'lc2407'!B34*W35/1000 -> 16.128 | J35: =+'lc2408'!B34*W35/1000 -> 16.488 | K35: =+'lc2409'!B34*W35/1000 -> 16.48 | L35: =+'lc2410'!B34*W35/1000 -> 16.32 | M35: =+'lc2411'!B34*W35/1000 -> 16.224 | N35: =+'lc2412'!B34*W35/1000 -> 16.512 | O35: =+'lc2501'!B34*W35/1000 -> 0 | P35: =+'lc2501'!C34*X35/1000 -> 0 | Q35: 0 | S35: =+AVERAGE(C35:O35) -> 14.857846 | W35: 0.16 | Y35: =+'lc2401'!G34 -> 21532 | Z35: =+'lc2402'!G34 -> 15802 | AA35: =+'lc2403'!G34 -> 20661 | AB35: =+'lc2404'!G34 -> 28223 | AC35: =+'lc2405'!G34 -> 11776 | AD35: =+'lc2406'!G34 -> 5387 | AE35: =+'lc2407'!G34 -> 155842 | AF35: =+'lc2408'!G34 -> 8643 | AG35: =+'lc2409'!G34 -> 9902 | AH35: =+'lc2410'!G34 -> 4169 | AI35: =+'lc2411'!G34 -> 7103 | AJ35: =+'lc2412'!G34 -> 216 | AK35: =+'lc2501'!G34 -> 0 | AO35: =+SUM(Y35:AL35) -> 289256 | AP35: =+AO35/AO34-1 -> 0.0029368016
B36: 45285 | C36: =+'lc2401'!B35*W36/1000 -> 15.656 | D36: =+'lc2402'!B35*W36/1000 -> 15.76 | E36: =+'lc2403'!B35*W36/1000 -> 15.792 | F36: =+'lc2404'!B35*W36/1000 -> 16.464 | G36: =+'lc2405'!B35*W36/1000 -> 16.504 | H36: =+'lc2406'!B35*W36/1000 -> 16.48 | I36: =+'lc2407'!B35*W36/1000 -> 16.456 | J36: =+'lc2408'!B35*W36/1000 -> 16.776 | K36: =+'lc2409'!B35*W36/1000 -> 16.696 | L36: =+'lc2410'!B35*W36/1000 -> 16.584 | M36: =+'lc2411'!B35*W36/1000 -> 16.472 | N36: =+'lc2412'!B35*W36/1000 -> 16.712 | O36: =+'lc2501'!B35*W36/1000 -> 0 | P36: =+'lc2501'!C35*X36/1000 -> 0 | Q36: 0 | S36: =+AVERAGE(C36:O36) -> 15.104 | W36: 0.16 | Y36: =+'lc2401'!G35 -> 19970 | Z36: =+'lc2402'!G35 -> 15931 | AA36: =+'lc2403'!G35 -> 22201 | AB36: =+'lc2404'!G35 -> 28995 | AC36: =+'lc2405'!G35 -> 11739 | AD36: =+'lc2406'!G35 -> 5440 | AE36: =+'lc2407'!G35 -> 159077 | AF36: =+'lc2408'!G35 -> 8610 | AG36: =+'lc2409'!G35 -> 9669 | AH36: =+'lc2410'!G35 -> 4122 | AI36: =+'lc2411'!G35 -> 6851 | AJ36: =+'lc2412'!G35 -> 209 | AK36: =+'lc2501'!G35 -> 0 | AO36: =+SUM(Y36:AL36) -> 292814 | AP36: =+AO36/AO35-1 -> 0.012300523
B37: 45286 | C37: =+'lc2401'!B36*W37/1000 -> 16.432 | D37: =+'lc2402'!B36*W37/1000 -> 16.48 | E37: =+'lc2403'!B36*W37/1000 -> 16.576 | F37: =+'lc2404'!B36*W37/1000 -> 17.152 | G37: =+'lc2405'!B36*W37/1000 -> 17.096 | H37: =+'lc2406'!B36*W37/1000 -> 17.168 | I37: =+'lc2407'!B36*W37/1000 -> 17.136 | J37: =+'lc2408'!B36*W37/1000 -> 17.344 | K37: =+'lc2409'!B36*W37/1000 -> 17.256 | L37: =+'lc2410'!B36*W37/1000 -> 17.088 | M37: =+'lc2411'!B36*W37/1000 -> 17 | N37: =+'lc2412'!B36*W37/1000 -> 17.216 | O37: =+'lc2501'!B36*W37/1000 -> 0 | P37: =+'lc2501'!C36*X37/1000 -> 0 | Q37: 0 | S37: =+AVERAGE(C37:O37) -> 15.688 | W37: 0.16 | Y37: =+'lc2401'!G36 -> 17115 | Z37: =+'lc2402'!G36 -> 15024 | AA37: =+'lc2403'!G36 -> 21176 | AB37: =+'lc2404'!G36 -> 28863 | AC37: =+'lc2405'!G36 -> 12787 | AD37: =+'lc2406'!G36 -> 6300 | AE37: =+'lc2407'!G36 -> 155209 | AF37: =+'lc2408'!G36 -> 8489 | AG37: =+'lc2409'!G36 -> 9161 | AH37: =+'lc2410'!G36 -> 4077 | AI37: =+'lc2411'!G36 -> 6612 | AJ37: =+'lc2412'!G36 -> 275 | AK37: =+'lc2501'!G36 -> 0 | AO37: =+SUM(Y37:AL37) -> 285088 | AP37: =+AO37/AO36-1 -> -0.02638535
B38: 45287 | C38: =+'lc2401'!B37*W38/1000 -> 16.256 | D38: =+'lc2402'!B37*W38/1000 -> 16.304 | E38: =+'lc2403'!B37*W38/1000 -> 16.336 | F38: =+'lc2404'!B37*W38/1000 -> 16.904 | G38: =+'lc2405'!B37*W38/1000 -> 16.864 | H38: =+'lc2406'!B37*W38/1000 -> 16.936 | I38: =+'lc2407'!B37*W38/1000 -> 16.912 | J38: =+'lc2408'!B37*W38/1000 -> 17.184 | K38: =+'lc2409'!B37*W38/1000 -> 17.168 | L38: =+'lc2410'!B37*W38/1000 -> 17 | M38: =+'lc2411'!B37*W38/1000 -> 16.976 | N38: =+'lc2412'!B37*W38/1000 -> 17.224 | O38: =+'lc2501'!B37*W38/1000 -> 0 | P38: =+'lc2501'!C37*X38/1000 -> 0 | Q38: 0 | S38: =+AVERAGE(C38:O38) -> 15.543385 | W38: 0.16 | Y38: =+'lc2401'!G37 -> 14190 | Z38: =+'lc2402'!G37 -> 14291 | AA38: =+'lc2403'!G37 -> 21009 | AB38: =+'lc2404'!G37 -> 29652 | AC38: =+'lc2405'!G37 -> 13450 | AD38: =+'lc2406'!G37 -> 6359 | AE38: =+'lc2407'!G37 -> 150793 | AF38: =+'lc2408'!G37 -> 8574 | AG38: =+'lc2409'!G37 -> 9070 | AH38: =+'lc2410'!G37 -> 4107 | AI38: =+'lc2411'!G37 -> 6452 | AJ38: =+'lc2412'!G37 -> 259 | AK38: =+'lc2501'!G37 -> 0 | AO38: =+SUM(Y38:AL38) -> 278206 | AP38: =+AO38/AO37-1 -> -0.024139915
B39: 45288 | C39: =+'lc2401'!B38*W39/1000 -> 16.192 | D39: =+'lc2402'!B38*W39/1000 -> 16.256 | E39: =+'lc2403'!B38*W39/1000 -> 16.352 | F39: =+'lc2404'!B38*W39/1000 -> 17 | G39: =+'lc2405'!B38*W39/1000 -> 17 | H39: =+'lc2406'!B38*W39/1000 -> 17.056 | I39: =+'lc2407'!B38*W39/1000 -> 17.048 | J39: =+'lc2408'!B38*W39/1000 -> 17.424 | K39: =+'lc2409'!B38*W39/1000 -> 17.272 | L39: =+'lc2410'!B38*W39/1000 -> 17.224 | M39: =+'lc2411'!B38*W39/1000 -> 17.224 | N39: =+'lc2412'!B38*W39/1000 -> 17.376 | O39: =+'lc2501'!B38*W39/1000 -> 0 | P39: =+'lc2501'!C38*X39/1000 -> 0 | Q39: 0 | S39: =+AVERAGE(C39:O39) -> 15.648 | W39: 0.16 | Y39: =+'lc2401'!G38 -> 13033 | Z39: =+'lc2402'!G38 -> 14530 | AA39: =+'lc2403'!G38 -> 21913 | AB39: =+'lc2404'!G38 -> 30141 | AC39: =+'lc2405'!G38 -> 13459 | AD39: =+'lc2406'!G38 -> 6411 | AE39: =+'lc2407'!G38 -> 152061 | AF39: =+'lc2408'!G38 -> 8656 | AG39: =+'lc2409'!G38 -> 9035 | AH39: =+'lc2410'!G38 -> 4109 | AI39: =+'lc2411'!G38 -> 6434 | AJ39: =+'lc2412'!G38 -> 260 | AK39: =+'lc2501'!G38 -> 0 | AO39: =+SUM(Y39:AL39) -> 280042 | AP39: =+AO39/AO38-1 -> 0.0065994263
B40: 45289 | C40: =+'lc2401'!B39*W40/1000 -> 16.176 | D40: =+'lc2402'!B39*W40/1000 -> 16.264 | E40: =+'lc2403'!B39*W40/1000 -> 16.376 | F40: =+'lc2404'!B39*W40/1000 -> 17.152 | G40: =+'lc2405'!B39*W40/1000 -> 17.136 | H40: =+'lc2406'!B39*W40/1000 -> 17.16 | I40: =+'lc2407'!B39*W40/1000 -> 17.232 | J40: =+'lc2408'!B39*W40/1000 -> 17.504 | K40: =+'lc2409'!B39*W40/1000 -> 17.416 | L40: =+'lc2410'!B39*W40/1000 -> 17.272 | M40: =+'lc2411'!B39*W40/1000 -> 17.176 | N40: =+'lc2412'!B39*W40/1000 -> 17.6 | O40: =+'lc2501'!B39*W40/1000 -> 0 | P40: =+'lc2501'!C39*X40/1000 -> 0 | Q40: 0 | S40: =+AVERAGE(C40:O40) -> 15.728 | W40: 0.16 | Y40: =+'lc2401'!G39 -> 11852 | Z40: =+'lc2402'!G39 -> 14973 | AA40: =+'lc2403'!G39 -> 23839 | AB40: =+'lc2404'!G39 -> 33648 | AC40: =+'lc2405'!G39 -> 13685 | AD40: =+'lc2406'!G39 -> 6621 | AE40: =+'lc2407'!G39 -> 142958 | AF40: =+'lc2408'!G39 -> 8526 | AG40: =+'lc2409'!G39 -> 8780 | AH40: =+'lc2410'!G39 -> 4102 | AI40: =+'lc2411'!G39 -> 6364 | AJ40: =+'lc2412'!G39 -> 260 | AK40: =+'lc2501'!G39 -> 0 | AO40: =+SUM(Y40:AL40) -> 275608 | AP40: =+AO40/AO39-1 -> -0.015833339
...

Sheet Market
A1: Conversion en Notas | B1: Industrial Grade | C1: Battery Grade | D1: SMM LC Idx | E1: Lithium Hydroxide BG | F1: Lithium Hydroxide Idx | G1: Lithium Hydroxide BG Fine | H1: Lithium Carbonate CIF China | I1: Lithium Hydroxide CIF China | J1: Lithium Hexafluorophosphate | K1: Lithium Fluoride BG | L1: Lithium Hydroxide IG | M1: Spodumene Concentrate IDX CIF China | N1: Spodumene Domestic China 5% | O1: Spodumene Domestic China 4% | P1: Spodumene Dometic China 3% | Q1: Spodumene 1,2% | R1: Spodumene 2% | S1: Spodumene 3% | T1: Lepidolite 1,5% | U1: Lepidolite 2% | V1: Montebrasite 6% | W1: Montebrasite 7% | X1: AUS Spodumene 6% Spot cif China | Y1: BRL Spodumene 6% Spot CIF China
A2: Dec 01, 2023 | B2: 118500 | C2: 130000 | D2: 128431 | E2: 119500 | F2: 119904 | G2: 128500 | H2: 18.505 | I2: 18.5 | J2: 82000 | K2: 259000 | L2: 111000 | M2: 1730 | N2: 9675 | O2: 8500 | P2: 8500 | Q2: 167.5 | R2: 300 | S2: 585 | T2: 2100 | U2: 3375 | V2: 12900 | W2: 15800
A3: Dec 04, 2023 | B3: 116000 | C3: 128000 | D3: 126864 | E3: 117500 | F3: 117936 | G3: 126500 | H3: 17.75 | I3: 18 | J3: 82000 | K3: 259000 | L3: 109000 | M3: 1700 | N3: 9335 | O3: 8185 | P3: 8185 | Q3: 167 | R3: 300 | S3: 585 | T3: 2100 | U3: 3375 | V3: 12900 | W3: 15800
A4: Dec 05, 2023 | B4: 113500 | C4: 126000 | D4: 124781 | E4: 115500 | F4: 115443 | G4: 124500 | H4: 17.6 | I4: 17.75 | J4: 81750 | K4: 259000 | L4: 107000 | M4: 1670 | N4: 9125 | O4: 7960 | P4: 7960 | Q4: 167.5 | R4: 300 | S4: 585 | T4: 2025 | U4: 3275 | V4: 12800 | W4: 15600
A5: Dec 06, 2023 | B5: 109500 | C5: 122500 | D5: 121771 | E5: 112500 | F5: 112411 | G5: 121000 | H5: 17.5 | I5: 17.5 | J5: 81500 | K5: 259000 | L5: 104000 | M5: 1655 | N5: 8900 | O5: 7735 | P5: 7735 | Q5: 167.5 | R5: 300 | S5: 585 | T5: 1975 | U5: 3200 | V5: 12600 | W5: 15300
A6: Dec 07, 2023 | B6: 107000 | C6: 120500 | D6: 119655 | E6: 110500 | F6: 110186 | G6: 118500 | H6: 17 | I6: 17.5 | J6: 80500 | K6: 259000 | L6: 102000 | M6: 1640 | N6: 8755 | O6: 7550 | P6: 7550 | Q6: 152.5 | R6: 280 | S6: 545 | T6: 1950 | U6: 3162.5 | V6: 12325 | W6: 14925
A7: Dec 11, 2023 | B7: 101500 | C7: 115000 | D7: 114815 | E7: 106500 | F7: 106772 | G7: 114500 | H7: 16.5 | I7: 16.75 | J7: 77500 | K7: 235500 | L7: 98500 | M7: 1565 | N7: 8285 | O7: 6970 | P7: 6970 | Q7: 152.5 | R7: 280 | S7: 545 | T7: 1875 | U7: 3050 | V7: 12275 | W7: 14850
A8: Dec 12, 2023 | B8: 98500 | C8: 112000 | D8: 112927 | E8: 103500 | F8: 103671 | G8: 111500 | H8: 16.25 | I8: 16.65 | J8: 77000 | K8: 235500 | L8: 95500 | M8: 1535 | N8: 8130 | O8: 6815 | P8: 6815 | Q8: 152.5 | R8: 280 | S8: 545 | T8: 1850 | U8: 3012.5 | V8: 12275 | W8: 14850
A9: Dec 13, 2023 | B9: 96000 | C9: 109000 | D9: 109468 | E9: 100500 | F9: 100118 | G9: 108500 | H9: 16 | I9: 16.5 | J9: 76500 | K9: 235500 | L9: 92500 | M9: 1515 | N9: 8050 | O9: 6650 | P9: 6650 | Q9: 152.5 | R9: 280 | S9: 545 | T9: 1825 | U9: 2975 | V9: 11775 | W9: 14275
A10: Dec 14, 2023 | B10: 94500 | C10: 106500 | D10: 106787 | E10: 98000 | F10: 97747 | G10: 106000 | H10: 15.75 | I10: 16.25 | J10: 76000 | K10: 235500 | L10: 90000 | M10: 1495 | N10: 7970 | O10: 6490 | P10: 6490 | Q10: 143.5 | R10: 262.5 | S10: 520 | T10: 1775 | U10: 2900 | V10: 11575 | W10: 14025
A11: Dec 15, 2023 | B11: 93750 | C11: 104500 | D11: 104371 | E11: 95750 | F11: 95250 | G11: 103750 | H11: 15.5 | I11: 16.25 | J11: 75500 | K11: 210300 | L11: 88000 | M11: 1470 | N11: 7890 | O11: 6360 | P11: 6360 | Q11: 143.5 | R11: 262.5 | S11: 520 | T11: 1725 | U11: 2862 | V11: 11275 | W11: 13650
A12: Dec 18, 2023 | B12: 93250 | C12: 103000 | D12: 102628 | E12: 93750 | F12: 93540 | G12: 101750 | H12: 15.25 | I12: 16 | J12: 75000 | K12: 210300 | L12: 86000 | M12: 1455 | N12: 7810 | O12: 6250 | P12: 6250 | Q12: 143.5 | R12: 262.5 | S12: 520 | T12: 1625 | U12: 2737.5 | V12: 10875 | W12: 13200
A13: Dec 19, 2023 | B13: 92750 | C13: 102000 | D13: 101066 | E13: 91750 | F13: 91790 | G13: 99750 | H13: 15 | I13: 16 | J13: 74500 | K13: 210300 | L13: 84000 | M13: 1440 | N13: 7740 | O13: 6185 | P13: 6185 | Q13: 143.5 | R13: 262.5 | S13: 520 | T13: 1550 | U13: 2625 | V13: 10675 | W13: 12950
... A34: Jan 31, 2024 | B34: 89200 | C34: 96750 | D34: 95640 | E34: 84650 | F34: 83538 | G34: 90550 | H34: 14 | I34: 13.75 | J34: 65000 | K34: 165000 | L34: 77000 | M34: 938 | N34: 6425 | O34: 5225 | P34: 3375 | Q34: 100 | R34: 183.5 | S34: 385 | T34: 1210 | U34: 2085 | V34: 9620 | W34: 11600
A35: Feb 01, 2024 | B35: 89500 | C35: 97050 | D35: 95730 | E35: 84850 | F35: 83819 | G35: 90750 | H35: 14 | I35: 13.75 | J35: 65000 | K35: 165000 | L35: 77000 | M35: 938 | N35: 6425 | O35: 5225 | P35: 3375 | Q35: 100 | R35: 183.5 | S35: 385 | T35: 1210 | U35: 2085 | V35: 9620 | W35: 11600 | X35: 900 | Y35: 825
A36: Feb 02, 2024 | B36: 89500 | C36: 97050 | D36: 95801 | E36: 84850 | F36: 83819 | G36: 90750 | H36: 14 | I36: 13.75 | J36: 65000 | K36: 165000 | L36: 77000 | M36: 938 | N36: 6425 | O36: 5225 | P36: 3375 | Q36: 100 | R36: 183.5 | S36: 385 | T36: 1210 | U36: 2085 | V36: 9620 | W36: 11600 | X36: 900 | Y36: 825
A37: Feb 05, 2024 | B37: 89500 | C37: 97050 | D37: 95801 | E37: 84950 | F37: 83837 | G37: 90850 | H37: 14 | I37: 13.75 | J37: 65000 | K37: 165000 | L37: 77000 | M37: 938 | N37: 6425 | O37: 5225 | P37: 3375 | Q37: 100 | R37: 183.5 | S37: 385 | T37: 1210 | U37: 2085 | V37: 9620 | W37: 11600 | X37: 900 | Y37: 825
A38: Feb 06, 2024 | B38: 89500 | C38: 97050 | D38: 95921 | E38: 85150 | F38: 83864 | G38: 91050 | H38: 14 | I38: 13.75 | J38: 65000 | K38: 165000 | L38: 77200 | M38: 938 | N38: 6425 | O38: 5225 | P38: 3375 | Q38: 100 | R38: 183.5 | S38: 385 | T38: 1210 | U38: 2085 | V38: 9620 | W38: 11600 | X38: 900 | Y38: 825
A39: Feb 07, 2024 | B39: 89500 | C39: 97050 | D39: 95921 | E39: 85150 | F39: 83869 | G39: 91050 | H39: 14 | I39: 13.75 | J39: 65000 | K39: 165000 | L39: 77200 | M39: 938 | N39: 6425 | O39: 5225 | P39: 3375 | Q39: 100 | R39: 183.5 | S39: 385 | T39: 1210 | U39: 2085 | V39: 9620 | W39: 11600 | X39: 900 | Y39: 825
A40: Feb 08, 2024 | B40: 89500 | C40: 97050 | D40: 95921 | E40: 85150 | F40: 83869 | G40: 91050 | H40: 14 | I40: 13.75 | J40: 65000 | K40: 165000 | L40: 77200 | M40: 938 | N40: 6425 | O40: 5225 | P40: 3375 | Q40: 100 | R40: 183.5 | S40: 385 | T40: 1210 | U40: 2085 | V40: 9620 | W40: 11600 | X40: 900 | Y40: 825
A41: Feb 19, 2024 | B41: 89400 | C41: 96900 | D41: 95732 | E41: 85150 | F41: 83923 | G41: 91050 | H41: 14 | I41: 13.75 | J41: 65000 | K41: 165000 | L41: 77200 | M41: 920 | N41: 6425 | O41: 5225 | P41: 3375 | Q41: 100 | R41: 183.5 | S41: 385 | T41: 1210 | U41: 2085 | V41: 9620 | W41: 11600 | X41: 900 | Y41: 825
A42: Feb 20, 2024 | B42: 89400 | C42: 96750 | D42: 95671 | E42: 85150 | F42: 83923 | G42: 91050 | H42: 14 | I42: 13.75 | J42: 65000 | K42: 165000 | L42: 77200 | M42: 910 | N42: 6425 | O42: 5225 | P42: 3375 | Q42: 100 | R42: 183.5 | S42: 385 | T42: 1210 | U42: 2085 | V42: 9620 | W42: 11600 | X42: 900 | Y42: 825
A43: Feb 21, 2024 | B43: 88750 | C43: 96150 | D43: 95489 | E43: 85050 | F43: 83878 | G43: 90950 | H43: 14 | I43: 13.75 | J43: 65000 | K43: 165000 | L43: 77200 | M43: 910 | N43: 6425 | O43: 5225 | P43: 3375 | Q43: 100 | R43: 183.5 | S43: 385 | T43: 1210 | U43: 2085 | V43: 9620 | W43: 11600 | X43: 900 | Y43: 825
A44: Feb 22, 2024 | B44: 88800 | C44: 96150 | D44: 95504 | E44: 85050 | F44: 83899 | G44: 90950 | H44: 14 | I44: 13.75 | J44: 65000 | K44: 165000 | L44: 77200 | M44: 910 | N44: 6425 | O44: 5225 | P44: 3375 | Q44: 100 | R44: 183.5 | S44: 385 | T44: 1210 | U44: 2085 | V44: 9620 | W44: 11600 | X44: 900 | Y44: 825
A45: Mar 19, 2024 | B45: 107500 | C45: 112550 | D45: 111376 | E45: 98750 | F45: 97424 | G45: 104650 | H45: 13.5 | I45: 13.83 | J45: 72000 | K45: 191300 | L45: 91000 | M45: 1075 | N45: 8165 | O45: 6655 | P45: 4485 | Q45: 121.5 | R45: 217.5 | S45: 432.5 | T45: 1260 | U45: 2150 | V45: 9620 | W45: 11600 | X45: 1095 | Y45: 1015
A46: Mar 25, 2024 | B46: 107900 | C46: 112450 | D46: 111548 | E46: 99250 | F46: 97988 | G46: 105150 | H46: 13.68 | I46: 13.85 | J46: 72000 | K46: 195800 | L46: 91500 | M46: 1083 | N46: 8175 | O46: 6665 | P46: 4485 | Q46: 128 | R46: 227.5 | S46: 443.5 | T46: 1320 | U46: 2220 | V46: 9620 | W46: 11600 | X46: 1100 | Y46: 1040
... A474: Jan 30, 2026 | B474: 157000 | C474: 160500 | D474: 159309 | E474: 158000 | F474: 158082 | G474: 163550 | H474: 20.9 | I474: 19.5 | J474: 142500 | K474: 273200 | L474: 148500 | M474: 2070 | N474: 14900 | O474: 12125 | P474: 9025 | Q474: 195 | R474: 320 | S474: 595 | T474: 3240 | U474: 4965 | V474: 15075 | W474: 16500 | X474: 2175 | Y474: 2170
A475: Feb 06, 2026 | B475: 131000 | C475: 134500 | D475: 136038 | E475: 132500 | F475: 134096 | G475: 139000 | H475: N/A | I475: N/A | J475: 126000 | K475: 250000 | L475: 122000 | M475: N/A | N475: 12925 | O475: 10600 | P475: 7725 | Q475: N/A | R475: N/A | S475: N/A | T475: 2875 | U475: 4375 | V475: 13000 | W475: 13900 | X475: N/A | Y475: N/A
A476: Feb 09, 2026 | B476: 132000 | C476: 135500 | D476: 134390 | E476: 133000 | F476: 134819 | G476: 139500 | H476: N/A | I476: N/A | J476: 125000 | K476: 250000 | L476: 122500 | M476: N/A | N476: 13015 | O476: 10675 | P476: 7785 | Q476: N/A | R476: N/A | S476: N/A | T476: 2875 | U476: 4375 | V476: 13000 | W476: 13900 | X476: N/A | Y476: N/A
A477: Feb 10, 2026 | B477: 132500 | C477: 136000 | D477: 134406 | E477: 133750 | F477: 135598 | G477: 140250 | H477: N/A | I477: N/A | J477: 125000 | K477: 250000 | L477: 123200 | M477: N/A | N477: 13015 | O477: 10675 | P477: 7785 | Q477: N/A | R477: N/A | S477: N/A | T477: 2875 | U477: 4375 | V477: 13000 | W477: 13900 | X477: N/A | Y477: N/A
A478: Feb 11, 2026 | B478: 134500 | C478: 138000 | D478: 138483 | E478: 134500 | F478: 136050 | G478: 141000 | H478: N/A | I478: N/A | J478: 125000 | K478: 250000 | L478: 123950 | M478: N/A | N478: 13090 | O478: 10730 | P478: 7840 | Q478: N/A | R478: N/A | S478: N/A | T478: 2915 | U478: 4415 | V478: 13100 | W478: 14000 | X478: N/A | Y478: N/A
A479: Feb 12, 2026 | B479: 139000 | C479: 142500 | D479: 142168 | E479: 136500 | F479: 137962 | G479: 143000 | H479: N/A | I479: N/A | J479: 125000 | K479: 250000 | L479: 125950 | M479: N/A | N479: 13250 | O479: 10840 | P479: 7940 | Q479: N/A | R479: N/A | S479: N/A | T479: 3065 | U479: 4575 | V479: 13250 | W479: 14200 | X479: N/A | Y479: N/A
A480: Feb 13, 2026 | B480: 140250 | C480: 143750 | D480: 143223 | E480: 137500 | F480: 139006 | G480: 144000 | H480: N/A | I480: N/A | J480: 125000 | K480: 238700 | L480: 126950 | M480: N/A | N480: 13375 | O480: 10925 | P480: 8000 | Q480: N/A | R480: N/A | S480: N/A | T480: 3125 | U480: 4640 | V480: 13340 | W480: 14300 | X480: N/A | Y480: N/A
A481: Feb 24, 2026 | B481: 148500 | C481: 152000 | D481: 152025 | E481: 144500 | F481: 145759 | G481: 151000 | H481: N/A | I481: N/A | J481: 125000 | K481: 238700 | L481: 133450 | M481: N/A | N481: 14000 | O481: 11300 | P481: 8200 | Q481: N/A | R481: N/A | S481: N/A | T481: 3250 | U481: 4825 | V481: 13600 | W481: 14700 | X481: N/A | Y481: N/A
A482: Feb 25, 2026 | B482: 158250 | C482: 161750 | D482: 161243 | E482: 153000 | F482: 153111 | G482: 159500 | H482: N/A | I482: N/A | J482: 125000 | K482: 238700 | L482: 141450 | M482: N/A | N482: 14950 | O482: 11850 | P482: 8600 | Q482: N/A | R482: N/A | S482: N/A | T482: 3600 | U482: 5400 | V482: 14100 | W482: 15300 | X482: N/A | Y482: N/A
A483: Feb 26, 2026 | B483: 169500 | C483: 173000 | D483: 172310 | E483: 163000 | F483: 161938 | G483: 169500 | H483: N/A | I483: N/A | J483: 125000 | K483: 238700 | L483: 151450 | M483: N/A | N483: 15850 | O483: 12500 | P483: 9100 | Q483: N/A | R483: N/A | S483: N/A | T483: 3800 | U483: 5700 | V483: 14500 | W483: 15800 | X483: N/A | Y483: N/A
A484: Feb 27, 2026 | B484: 168500 | C484: 172000 | D484: 171196 | E484: 162600 | F484: 161638 | G484: 169100 | H484: N/A | I484: N/A | J484: 125000 | K484: 260750 | L484: 151050 | M484: N/A | N484: 15850 | O484: 12500 | P484: 9100 | Q484: N/A | R484: N/A | S484: N/A | T484: 3725 | U484: 5600 | V484: 14075 | W484: 15350 | X484: N/A | Y484: N/A
A485: Mar 02, 2026 | B485: 169000 | C485: 172500 | D485: 171847 | E485: 162600 | F485: 161742 | G485: 169100 | H485: N/A | I485: N/A | J485: 125000 | K485: 260750 | L485: 151050 | M485: N/A | N485: 15850 | O485: 12500 | P485: 9100 | Q485: N/A | R485: N/A | S485: N/A | T485: 3685 | U485: 5525 | V485: 13775 | W485: 15050 | X485: N/A | Y485: N/A
A486: Mar 03, 2026 | B486: 157500 | C486: 161000 | D486: 161266 | E486: 155600 | F486: 155853 | G486: 162100 | H486: N/A | I486: N/A | J486: 121500 | K486: 260750 | L486: 144050 | M486: N/A | N486: 15150 | O486: 12125 | P486: 8850 | Q486: N/A | R486: N/A | S486: N/A | T486: 3565 | U486: 5350 | V486: 13225 | W486: 14475 | X486: N/A | Y486: N/A
... A492: Mar 11, 2026 | B492: 155750 | C492: 159000 | D492: 159393 | E492: 152000 | F492: 152874 | G492: 158500 | H492: N/A | I492: N/A | J492: 112500 | K492: 273500 | L492: 140050 | M492: N/A | N492: 15300 | O492: 12325 | P492: 9075 | Q492: N/A | R492: N/A | S492: N/A | T492: 3440 | U492: 5140 | V492: 13175 | W492: 14350 | X492: N/A | Y492: N/A

Sheet lc2401
A1: Date | B1: Latest | C1: Prev.Close | D1: Volume | E1: Prev.Settle | F1: Open | G1: Open Interest | H1: Latest % | I1: O.I %
A2: Nov 08, 2023 15:00:00 | B2: 145350 | C2: 142550 | D2: 584534 | E2: 143800 | F2: 141900 | G2: 105467 | H2: =+B2/E2-1 -> 0.01077886
A3: Nov 09, 2023 15:00:00 | B3: 144150 | C3: 145350 | D3: 323961 | E3: 143100 | F3: 145300 | G3: 106948 | H3: =+B3/E3-1 -> 0.0073375262 | I3: =+G3/G2-1 -> 0.014042307
A4: Nov 10, 2023 15:00:00 | B4: 148900 | C4: 144150 | D4: 374012 | E4: 144600 | F4: 144600 | G4: 98275 | H4: =+B4/E4-1 -> 0.029737206 | I4: =+G4/G3-1 -> -0.081095486
A5: Nov 13, 2023 15:00:00 | B5: 141650 | C5: 148900 | D5: 382854 | E5: 147500 | F5: 149800 | G5: 96195 | H5: =+B5/E5-1 -> -0.039661017 | I5: =+G5/G4-1 -> -0.021165098
A6: Nov 14, 2023 15:00:00 | B6: 142550 | C6: 141650 | D6: 367056 | E6: 147200 | F6: 141150 | G6: 99509 | H6: =+B6/E6-1 -> -0.031589674 | I6: =+G6/G5-1 -> 0.034450855
A7: Nov 15, 2023 15:00:00 | B7: 142600 | C7: 142550 | D7: 269895 | E7: 142800 | F7: 144000 | G7: 107801 | H7: =+B7/E7-1 -> -0.0014005602 | I7: =+G7/G6-1 -> 0.083329146
A8: Nov 16, 2023 15:00:00 | B8: 140900 | C8: 142600 | D8: 234117 | E8: 142800 | F8: 142500 | G8: 113750 | H8: =+B8/E8-1 -> -0.013305322 | I8: =+G8/G7-1 -> 0.055185017
A9: Nov 17, 2023 15:00:00 | B9: 138000 | C9: 140900 | D9: 260599 | E9: 141450 | F9: 139500 | G9: 113625 | H9: =+B9/E9-1 -> -0.024390244 | I9: =+G9/G8-1 -> -0.0010989011
A10: Nov 20, 2023 15:00:00 | B10: 137200 | C10: 138000 | D10: 242544 | E10: 138800 | F10: 138000 | G10: 117451 | H10: =+B10/E10-1 -> -0.011527378 | I10: =+G10/G9-1 -> 0.033672167
A11: Nov 21, 2023 15:00:00 | B11: 132300 | C11: 137200 | D11: 342945 | E11: 138600 | F11: 137900 | G11: 119970 | H11: =+B11/E11-1 -> -0.045454545 | I11: =+G11/G10-1 -> 0.021447242
A12: Nov 22, 2023 15:00:00 | B12: 124700 | C12: 132300 | D12: 531056 | E12: 134050 | F12: 132300 | G12: 117807 | H12: =+B12/E12-1 -> -0.069750093 | I12: =+G12/G11-1 -> -0.018029507
A13: Nov 23, 2023 15:00:00 | B13: 124800 | C13: 124700 | D13: 581420 | E13: 127600 | F13: 124400 | G13: 115316 | H13: =+B13/E13-1 -> -0.021943574 | I13: =+G13/G12-1 -> -0.021144754
A14: Nov 24, 2023 15:00:00 | B14: 124050 | C14: 124800 | D14: 699474 | E14: 122900 | F14: 125050 | G14: 121691 | H14: =+B14/E14-1 -> 0.009357201 | I14: =+G14/G13-1 -> 0.055282875
... A49: Jan 15, 2024 15:00:00 | B49: 96800 | C49: 97400 | D49: 63 | E49: 97500 | F49: 97000 | G49: 0 | H49: =+B49/E49-1 -> -0.0071794872 | I49: =+G49/G48-1 -> -1

Sheet lc2402
A1: Date | B1: Latest | C1: Prev.Close | D1: Volume | E1: Prev.Settle | F1: Open | G1: Open Interest | H1: Var % | I1: O.I %
A2: Nov 08, 2023 15:00:00 | B2: 136000 | C2: 134250 | D2: 3354 | E2: 135750 | F2: 134250 | G2: 5489 | H2: =+B2/E2-1 -> 0.0018416206
A3: Nov 09, 2023 15:00:00 | B3: 135700 | C3: 136000 | D3: 2076 | E3: 134350 | F3: 136000 | G3: 5501 | H3: =+B3/E3-1 -> 0.010048381 | I3: =+G3/G2-1 -> 0.0021861906
A4: Nov 10, 2023 15:00:00 | B4: 139800 | C4: 135700 | D4: 2056 | E4: 136100 | F4: 136200 | G4: 5262 | H4: =+B4/E4-1 -> 0.027185893 | I4: =+G4/G3-1 -> -0.043446646
A5: Nov 13, 2023 15:00:00 | B5: 134550 | C5: 139800 | D5: 2563 | E5: 138700 | F5: 139000 | G5: 5545 | H5: =+B5/E5-1 -> -0.029920692 | I5: =+G5/G4-1 -> 0.053781832
A6: Nov 14, 2023 15:00:00 | B6: 136250 | C6: 134550 | D6: 2467 | E6: 138950 | F6: 134050 | G6: 5802 | H6: =+B6/E6-1 -> -0.01943145 | I6: =+G6/G5-1 -> 0.046348061
A7: Nov 15, 2023 15:00:00 | B7: 136700 | C7: 136250 | D7: 1916 | E7: 136150 | F7: 139800 | G7: 6023 | H7: =+B7/E7-1 -> 0.0040396621 | I7: =+G7/G6-1 -> 0.038090314
A8: Nov 16, 2023 15:00:00 | B8: 135900 | C8: 136700 | D8: 1123 | E8: 136950 | F8: 136050 | G8: 6118 | H8: =+B8/E8-1 -> -0.0076670318 | I8: =+G8/G7-1 -> 0.015772871
